Workbook

Sheet 대시보드 Dashboard
B1: API 연동 개발 트래커 — 대시보드 · API Integration Tracker — Dashboard
B2: ="오늘 Today "&TEXT(TODAY(),"yyyy-mm-dd")&" · 카테고리 시트에서 자동 집계 · auto-counted from the category sheets · 데이터 Data: SharePoint API Dev Tracker (19 Oct) + OMH-CRM (18 Oct)" -> 오늘 Today 2026-10-30 · 카테고리 시트에서 자동 집계 · auto-counted from the category sheets · 데이터 Data: SharePoint API Dev Tracker (19 Oct) + OMH-CRM (18 Oct)
B4: 전체 Total | D4: 라이브 Live | F4: 개발·테스트 Dev / Test | H4: 계약·NDA NDA / Contract | J4: 파이프라인 Pipeline | L4: 60일+ 정체 Stalled 60d+ | N4: 체이스 지연·필요 Chase overdue / needed
B5: =COUNTA('스위칭 업체 Switch vendors'!$G$5:$G$400)+COUNTA('스위칭 연동 Switching'!$G$5:$G$400)+COUNTA('서드파티 연동 3rd Party'!$G$5:$G$399)+COUNTA('우리가 공급사 OMH Supply'!$G$5:$G$399)+COUNTA('상호연동 Two-way'!$G$5:$G$400) -> 142 | D5: =COUNTIF('스위칭 업체 Switch vendors'!$B$5:$B$400,"Live")+COUNTIF('스위칭 업체 Switch vendors'!$B$5:$B$400,"Partially Live")+COUNTIF('스위칭 연동 Switching'!$B$5:$B$400,"Live")+COUNTIF('스위칭 연동 Switching'!$B$5:$B$400,"Partially Live")+COUNTIF('서드파티 연동 3rd Party'!$B$5:$B$399,"Live")+COUNTIF('서드파티 연동 3rd Party'!$B$5:$B$399,"Partially Live")+COUNTIF('우리가 공급사 OMH Supply'!$B$5:$B$399,"Live")+COUNTIF('우리가 공급사 OMH Supply'!$B$5:$B$399,"Partially Live")+COUNTIF('상호연동 Two-way'!$B$5:$B$400,"Live")+COUNTIF('상호연동 Two-way'!$B$5:$B$400,"Partially Live") -> 35 | F5: =COUNTIF('스위칭 업체 Switch vendors'!$B$5:$B$400,"In Development")+COUNTIF('스위칭 업체 Switch vendors'!$B$5:$B$400,"Testing")+COUNTIF('스위칭 업체 Switch vendors'!$B$5:$B$400,"Pending Live")+COUNTIF('스위칭 연동 Switching'!$B$5:$B$400,"In Development")+COUNTIF('스위칭 연동 Switching'!$B$5:$B$400,"Testing")+COUNTIF('스위칭 연동 Switching'!$B$5:$B$400,"Pending Live")+COUNTIF('서드파티 연동 3rd Party'!$B$5:$B$399,"In Development")+COUNTIF('서드파티 연동 3rd Party'!$B$5:$B$399,"Testing")+COUNTIF('서드파티 연동 3rd Party'!$B$5:$B$399,"Pending Live")+COUNTIF('우리가 공급사 OMH Supply'!$B$5:$B$399,"In Development")+COUNTIF('우리가 공급사 OMH Supply'!$B$5:$B$399,"Testing")+COUNTIF('우리가 공급사 OMH Supply'!$B$5:$B$399,"Pending Live")+COUNTIF('상호연동 Two-way'!$B$5:$B$400,"In Development")+COUNTIF('상호연동 Two-way'!$B$5:$B$400,"Testing")+COUNTIF('상호연동 Two-way'!$B$5:$B$400,"Pending Live") -> 14 | H5: =COUNTIF('스위칭 업체 Switch vendors'!$B$5:$B$400,"NDA/Contract")+COUNTIF('스위칭 연동 Switching'!$B$5:$B$400,"NDA/Contract")+COUNTIF('서드파티 연동 3rd Party'!$B$5:$B$399,"NDA/Contract")+COUNTIF('우리가 공급사 OMH Supply'!$B$5:$B$399,"NDA/Contract")+COUNTIF('상호연동 Two-way'!$B$5:$B$400,"NDA/Contract") -> 16 | J5: =COUNTIF('스위칭 업체 Switch vendors'!$B$5:$B$400,"Pipeline")+COUNTIF('스위칭 업체 Switch vendors'!$B$5:$B$400,"Contact")+COUNTIF('스위칭 연동 Switching'!$B$5:$B$400,"Pipeline")+COUNTIF('스위칭 연동 Switching'!$B$5:$B$400,"Contact")+COUNTIF('서드파티 연동 3rd Party'!$B$5:$B$399,"Pipeline")+COUNTIF('서드파티 연동 3rd Party'!$B$5:$B$399,"Contact")+COUNTIF('우리가 공급사 OMH Supply'!$B$5:$B$399,"Pipeline")+COUNTIF('우리가 공급사 OMH Supply'!$B$5:$B$399,"Contact")+COUNTIF('상호연동 Two-way'!$B$5:$B$400,"Pipeline")+COUNTIF('상호연동 Two-way'!$B$5:$B$400,"Contact") -> 77 | L5: =COUNTIF('스위칭 업체 Switch vendors'!$V$5:$V$400,"Stalled 60d+")+COUNTIF('스위칭 업체 Switch vendors'!$V$5:$V$400,"Stalled 90d+")+COUNTIF('스위칭 연동 Switching'!$S$5:$S$400,"Stalled 60d+")+COUNTIF('스위칭 연동 Switching'!$S$5:$S$400,"Stalled 90d+")+COUNTIF('서드파티 연동 3rd Party'!$S$5:$S$399,"Stalled 60d+")+COUNTIF('서드파티 연동 3rd Party'!$S$5:$S$399,"Stalled 90d+")+COUNTIF('우리가 공급사 OMH Supply'!$S$5:$S$399,"Stalled 60d+")+COUNTIF('우리가 공급사 OMH Supply'!$S$5:$S$399,"Stalled 90d+")+COUNTIF('상호연동 Two-way'!$V$5:$V$400,"Stalled 60d+")+COUNTIF('상호연동 Two-way'!$V$5:$V$400,"Stalled 90d+") -> 14 | N5: =COUNTIF('스위칭 업체 Switch vendors'!$AC$5:$AC$400,"Chase Overdue")+COUNTIF('스위칭 업체 Switch vendors'!$AC$5:$AC$400,"Chase Needed")+COUNTIF('스위칭 연동 Switching'!$Z$5:$Z$400,"Chase Overdue")+COUNTIF('스위칭 연동 Switching'!$Z$5:$Z$400,"Chase Needed")+COUNTIF('서드파티 연동 3rd Party'!$Z$5:$Z$399,"Chase Overdue")+COUNTIF('서드파티 연동 3rd Party'!$Z$5:$Z$399,"Chase Needed")+COUNTIF('우리가 공급사 OMH Supply'!$Z$5:$Z$399,"Chase Overdue")+COUNTIF('우리가 공급사 OMH Supply'!$Z$5:$Z$399,"Chase Needed")+COUNTIF('상호연동 Two-way'!$AC$5:$AC$400,"Chase Overdue")+COUNTIF('상호연동 Two-way'!$AC$5:$AC$400,"Chase Needed") -> 45
B8: 카테고리 × 개발 상태 · Category × status | O8: 지역 × 카테고리 (진행 중) · Region × category (open items)
B9: 카테고리 · Category | C9: Live | D9: Partially Live | E9: Pending Live | F9: Testing | G9: In Development | H9: NDA/Contract | I9: Pipeline | J9: Contact | K9: 보류/드롭 Hold/Drop | L9: 합계 Total | O9: 지역 · Region | P9: 스위칭 업체 Switch vendors | Q9: 스위칭 연동 Switching | R9: 서드파티 연동 3rd Party | S9: 우리가 공급사 OMH Supply | T9: 상호연동 Two-way | U9: 합계 Total
B10: 스위칭 업체 Switch vendors | C10: =COUNTIF('스위칭 업체 Switch vendors'!$B$5:$B$400,"Live") -> 0 | D10: =COUNTIF('스위칭 업체 Switch vendors'!$B$5:$B$400,"Partially Live") -> 0 | E10: =COUNTIF('스위칭 업체 Switch vendors'!$B$5:$B$400,"Pending Live") -> 0 | F10: =COUNTIF('스위칭 업체 Switch vendors'!$B$5:$B$400,"Testing") -> 1 | G10: =COUNTIF('스위칭 업체 Switch vendors'!$B$5:$B$400,"In Development") -> 1 | H10: =COUNTIF('스위칭 업체 Switch vendors'!$B$5:$B$400,"NDA/Contract") -> 0 | I10: =COUNTIF('스위칭 업체 Switch vendors'!$B$5:$B$400,"Pipeline") -> 0 | J10: =COUNTIF('스위칭 업체 Switch vendors'!$B$5:$B$400,"Contact") -> 6 | K10: =COUNTA('스위칭 업체 Switch vendors'!$D$5:$D$400) -> 5 | L10: =COUNTA('스위칭 업체 Switch vendors'!$G$5:$G$400) -> 8 | O10: 한국 · Korea | P10: =COUNTIFS('스위칭 업체 Switch vendors'!$E$5:$E$400,"한국 · Korea",'스위칭 업체 Switch vendors'!$B$5:$B$400,"<>Live",'스위칭 업체 Switch vendors'!$D$5:$D$400,"") -> 0 | Q10: =COUNTIFS('스위칭 연동 Switching'!$E$5:$E$400,"한국 · Korea",'스위칭 연동 Switching'!$B$5:$B$400,"<>Live",'스위칭 연동 Switching'!$D$5:$D$400,"") -> 0 | R10: =COUNTIFS('서드파티 연동 3rd Party'!$E$5:$E$399,"한국 · Korea",'서드파티 연동 3rd Party'!$B$5:$B$399,"<>Live",'서드파티 연동 3rd Party'!$D$5:$D$399,"") -> 0 | S10: =COUNTIFS('우리가 공급사 OMH Supply'!$E$5:$E$399,"한국 · Korea",'우리가 공급사 OMH Supply'!$B$5:$B$399,"<>Live",'우리가 공급사 OMH Supply'!$D$5:$D$399,"") -> 8 | T10: =COUNTIFS('상호연동 Two-way'!$E$5:$E$400,"한국 · Korea",'상호연동 Two-way'!$B$5:$B$400,"<>Live",'상호연동 Two-way'!$D$5:$D$400,"") -> 0 | U10: =SUM(P10:T10) -> 8
B11: 스위칭 연동 Switching | C11: =COUNTIF('스위칭 연동 Switching'!$B$5:$B$400,"Live") -> 0 | D11: =COUNTIF('스위칭 연동 Switching'!$B$5:$B$400,"Partially Live") -> 0 | E11: =COUNTIF('스위칭 연동 Switching'!$B$5:$B$400,"Pending Live") -> 0 | F11: =COUNTIF('스위칭 연동 Switching'!$B$5:$B$400,"Testing") -> 0 | G11: =COUNTIF('스위칭 연동 Switching'!$B$5:$B$400,"In Development") -> 0 | H11: =COUNTIF('스위칭 연동 Switching'!$B$5:$B$400,"NDA/Contract") -> 3 | I11: =COUNTIF('스위칭 연동 Switching'!$B$5:$B$400,"Pipeline") -> 0 | J11: =COUNTIF('스위칭 연동 Switching'!$B$5:$B$400,"Contact") -> 13 | K11: =COUNTA('스위칭 연동 Switching'!$D$5:$D$400) -> 0 | L11: =COUNTA('스위칭 연동 Switching'!$G$5:$G$400) -> 16 | O11: 일본 · Japan | P11: =COUNTIFS('스위칭 업체 Switch vendors'!$E$5:$E$400,"일본 · Japan",'스위칭 업체 Switch vendors'!$B$5:$B$400,"<>Live",'스위칭 업체 Switch vendors'!$D$5:$D$400,"") -> 0 | Q11: =COUNTIFS('스위칭 연동 Switching'!$E$5:$E$400,"일본 · Japan",'스위칭 연동 Switching'!$B$5:$B$400,"<>Live",'스위칭 연동 Switching'!$D$5:$D$400,"") -> 1 | R11: =COUNTIFS('서드파티 연동 3rd Party'!$E$5:$E$399,"일본 · Japan",'서드파티 연동 3rd Party'!$B$5:$B$399,"<>Live",'서드파티 연동 3rd Party'!$D$5:$D$399,"") -> 3 | S11: =COUNTIFS('우리가 공급사 OMH Supply'!$E$5:$E$399,"일본 · Japan",'우리가 공급사 OMH Supply'!$B$5:$B$399,"<>Live",'우리가 공급사 OMH Supply'!$D$5:$D$399,"") -> 2 | T11: =COUNTIFS('상호연동 Two-way'!$E$5:$E$400,"일본 · Japan",'상호연동 Two-way'!$B$5:$B$400,"<>Live",'상호연동 Two-way'!$D$5:$D$400,"") -> 0 | U11: =SUM(P11:T11) -> 6
B12: 서드파티 연동 3rd Party | C12: =COUNTIF('서드파티 연동 3rd Party'!$B$5:$B$399,"Live") -> 0 | D12: =COUNTIF('서드파티 연동 3rd Party'!$B$5:$B$399,"Partially Live") -> 0 | E12: =COUNTIF('서드파티 연동 3rd Party'!$B$5:$B$399,"Pending Live") -> 0 | F12: =COUNTIF('서드파티 연동 3rd Party'!$B$5:$B$399,"Testing") -> 0 | G12: =COUNTIF('서드파티 연동 3rd Party'!$B$5:$B$399,"In Development") -> 0 | H12: =COUNTIF('서드파티 연동 3rd Party'!$B$5:$B$399,"NDA/Contract") -> 0 | I12: =COUNTIF('서드파티 연동 3rd Party'!$B$5:$B$399,"Pipeline") -> 0 | J12: =COUNTIF('서드파티 연동 3rd Party'!$B$5:$B$399,"Contact") -> 4 | K12: =COUNTA('서드파티 연동 3rd Party'!$D$5:$D$399) -> 0 | L12: =COUNTA('서드파티 연동 3rd Party'!$G$5:$G$399) -> 4 | O12: 중화권 · Greater China | P12: =COUNTIFS('스위칭 업체 Switch vendors'!$E$5:$E$400,"중화권 · Greater China",'스위칭 업체 Switch vendors'!$B$5:$B$400,"<>Live",'스위칭 업체 Switch vendors'!$D$5:$D$400,"") -> 1 | Q12: =COUNTIFS('스위칭 연동 Switching'!$E$5:$E$400,"중화권 · Greater China",'스위칭 연동 Switching'!$B$5:$B$400,"<>Live",'스위칭 연동 Switching'!$D$5:$D$400,"") -> 1 | R12: =COUNTIFS('서드파티 연동 3rd Party'!$E$5:$E$399,"중화권 · Greater China",'서드파티 연동 3rd Party'!$B$5:$B$399,"<>Live",'서드파티 연동 3rd Party'!$D$5:$D$399,"") -> 1 | S12: =COUNTIFS('우리가 공급사 OMH Supply'!$E$5:$E$399,"중화권 · Greater China",'우리가 공급사 OMH Supply'!$B$5:$B$399,"<>Live",'우리가 공급사 OMH Supply'!$D$5:$D$399,"") -> 22 | T12: =COUNTIFS('상호연동 Two-way'!$E$5:$E$400,"중화권 · Greater China",'상호연동 Two-way'!$B$5:$B$400,"<>Live",'상호연동 Two-way'!$D$5:$D$400,"") -> 1 | U12: =SUM(P12:T12) -> 26
B13: 우리가 공급사 OMH Supply | C13: =COUNTIF('우리가 공급사 OMH Supply'!$B$5:$B$399,"Live") -> 31 | D13: =COUNTIF('우리가 공급사 OMH Supply'!$B$5:$B$399,"Partially Live") -> 0 | E13: =COUNTIF('우리가 공급사 OMH Supply'!$B$5:$B$399,"Pending Live") -> 1 | F13: =COUNTIF('우리가 공급사 OMH Supply'!$B$5:$B$399,"Testing") -> 2 | G13: =COUNTIF('우리가 공급사 OMH Supply'!$B$5:$B$399,"In Development") -> 7 | H13: =COUNTIF('우리가 공급사 OMH Supply'!$B$5:$B$399,"NDA/Contract") -> 5 | I13: =COUNTIF('우리가 공급사 OMH Supply'!$B$5:$B$399,"Pipeline") -> 2 | J13: =COUNTIF('우리가 공급사 OMH Supply'!$B$5:$B$399,"Contact") -> 46 | K13: =COUNTA('우리가 공급사 OMH Supply'!$D$5:$D$399) -> 1 | L13: =COUNTA('우리가 공급사 OMH Supply'!$G$5:$G$399) -> 94 | O13: 동남아 · SE Asia | P13: =COUNTIFS('스위칭 업체 Switch vendors'!$E$5:$E$400,"동남아 · SE Asia",'스위칭 업체 Switch vendors'!$B$5:$B$400,"<>Live",'스위칭 업체 Switch vendors'!$D$5:$D$400,"") -> 0 | Q13: =COUNTIFS('스위칭 연동 Switching'!$E$5:$E$400,"동남아 · SE Asia",'스위칭 연동 Switching'!$B$5:$B$400,"<>Live",'스위칭 연동 Switching'!$D$5:$D$400,"") -> 3 | R13: =COUNTIFS('서드파티 연동 3rd Party'!$E$5:$E$399,"동남아 · SE Asia",'서드파티 연동 3rd Party'!$B$5:$B$399,"<>Live",'서드파티 연동 3rd Party'!$D$5:$D$399,"") -> 0 | S13: =COUNTIFS('우리가 공급사 OMH Supply'!$E$5:$E$399,"동남아 · SE Asia",'우리가 공급사 OMH Supply'!$B$5:$B$399,"<>Live",'우리가 공급사 OMH Supply'!$D$5:$D$399,"") -> 17 | T13: =COUNTIFS('상호연동 Two-way'!$E$5:$E$400,"동남아 · SE Asia",'상호연동 Two-way'!$B$5:$B$400,"<>Live",'상호연동 Two-way'!$D$5:$D$400,"") -> 7 | U13: =SUM(P13:T13) -> 27
B14: 상호연동 Two-way | C14: =COUNTIF('상호연동 Two-way'!$B$5:$B$400,"Live") -> 4 | D14: =COUNTIF('상호연동 Two-way'!$B$5:$B$400,"Partially Live") -> 0 | E14: =COUNTIF('상호연동 Two-way'!$B$5:$B$400,"Pending Live") -> 0 | F14: =COUNTIF('상호연동 Two-way'!$B$5:$B$400,"Testing") -> 0 | G14: =COUNTIF('상호연동 Two-way'!$B$5:$B$400,"In Development") -> 2 | H14: =COUNTIF('상호연동 Two-way'!$B$5:$B$400,"NDA/Contract") -> 8 | I14: =COUNTIF('상호연동 Two-way'!$B$5:$B$400,"Pipeline") -> 0 | J14: =COUNTIF('상호연동 Two-way'!$B$5:$B$400,"Contact") -> 6 | K14: =COUNTA('상호연동 Two-way'!$D$5:$D$400) -> 0 | L14: =COUNTA('상호연동 Two-way'!$G$5:$G$400) -> 20 | O14: 인도 · India | P14: =COUNTIFS('스위칭 업체 Switch vendors'!$E$5:$E$400,"인도 · India",'스위칭 업체 Switch vendors'!$B$5:$B$400,"<>Live",'스위칭 업체 Switch vendors'!$D$5:$D$400,"") -> 1 | Q14: =COUNTIFS('스위칭 연동 Switching'!$E$5:$E$400,"인도 · India",'스위칭 연동 Switching'!$B$5:$B$400,"<>Live",'스위칭 연동 Switching'!$D$5:$D$400,"") -> 4 | R14: =COUNTIFS('서드파티 연동 3rd Party'!$E$5:$E$399,"인도 · India",'서드파티 연동 3rd Party'!$B$5:$B$399,"<>Live",'서드파티 연동 3rd Party'!$D$5:$D$399,"") -> 0 | S14: =COUNTIFS('우리가 공급사 OMH Supply'!$E$5:$E$399,"인도 · India",'우리가 공급사 OMH Supply'!$B$5:$B$399,"<>Live",'우리가 공급사 OMH Supply'!$D$5:$D$399,"") -> 9 | T14: =COUNTIFS('상호연동 Two-way'!$E$5:$E$400,"인도 · India",'상호연동 Two-way'!$B$5:$B$400,"<>Live",'상호연동 Two-way'!$D$5:$D$400,"") -> 1 | U14: =SUM(P14:T14) -> 15
B15: 합계 · Total | C15: =SUM(C10:C14) -> 35 | D15: =SUM(D10:D14) -> 0 | E15: =SUM(E10:E14) -> 1 | F15: =SUM(F10:F14) -> 3 | G15: =SUM(G10:G14) -> 10 | H15: =SUM(H10:H14) -> 16 | I15: =SUM(I10:I14) -> 2 | J15: =SUM(J10:J14) -> 75 | ... L15: =SUM(L10:L14) -> 142 | O15: 중동·러시아 · ME & Russia | P15: =COUNTIFS('스위칭 업체 Switch vendors'!$E$5:$E$400,"중동·러시아 · ME & Russia",'스위칭 업체 Switch vendors'!$B$5:$B$400,"<>Live",'스위칭 업체 Switch vendors'!$D$5:$D$400,"") -> 0 | Q15: =COUNTIFS('스위칭 연동 Switching'!$E$5:$E$400,"중동·러시아 · ME & Russia",'스위칭 연동 Switching'!$B$5:$B$400,"<>Live",'스위칭 연동 Switching'!$D$5:$D$400,"") -> 2 | R15: =COUNTIFS('서드파티 연동 3rd Party'!$E$5:$E$399,"중동·러시아 · ME & Russia",'서드파티 연동 3rd Party'!$B$5:$B$399,"<>Live",'서드파티 연동 3rd Party'!$D$5:$D$399,"") -> 0 | S15: =COUNTIFS('우리가 공급사 OMH Supply'!$E$5:$E$399,"중동·러시아 · ME & Russia",'우리가 공급사 OMH Supply'!$B$5:$B$399,"<>Live",'우리가 공급사 OMH Supply'!$D$5:$D$399,"") -> 3 | T15: =COUNTIFS('상호연동 Two-way'!$E$5:$E$400,"중동·러시아 · ME & Russia",'상호연동 Two-way'!$B$5:$B$400,"<>Live",'상호연동 Two-way'!$D$5:$D$400,"") -> 4 | U15: =SUM(P15:T15) -> 9
O16: 유럽·미주 · Europe & Americas | P16: =COUNTIFS('스위칭 업체 Switch vendors'!$E$5:$E$400,"유럽·미주 · Europe & Americas",'스위칭 업체 Switch vendors'!$B$5:$B$400,"<>Live",'스위칭 업체 Switch vendors'!$D$5:$D$400,"") -> 1 | Q16: =COUNTIFS('스위칭 연동 Switching'!$E$5:$E$400,"유럽·미주 · Europe & Americas",'스위칭 연동 Switching'!$B$5:$B$400,"<>Live",'스위칭 연동 Switching'!$D$5:$D$400,"") -> 5 | R16: =COUNTIFS('서드파티 연동 3rd Party'!$E$5:$E$399,"유럽·미주 · Europe & Americas",'서드파티 연동 3rd Party'!$B$5:$B$399,"<>Live",'서드파티 연동 3rd Party'!$D$5:$D$399,"") -> 0 | S16: =COUNTIFS('우리가 공급사 OMH Supply'!$E$5:$E$399,"유럽·미주 · Europe & Americas",'우리가 공급사 OMH Supply'!$B$5:$B$399,"<>Live",'우리가 공급사 OMH Supply'!$D$5:$D$399,"") -> 0 | T16: =COUNTIFS('상호연동 Two-way'!$E$5:$E$400,"유럽·미주 · Europe & Americas",'상호연동 Two-way'!$B$5:$B$400,"<>Live",'상호연동 Two-way'!$D$5:$D$400,"") -> 3 | U16: =SUM(P16:T16) -> 9
O17: 글로벌 · Global | P17: =COUNTIFS('스위칭 업체 Switch vendors'!$E$5:$E$400,"글로벌 · Global",'스위칭 업체 Switch vendors'!$B$5:$B$400,"<>Live",'스위칭 업체 Switch vendors'!$D$5:$D$400,"") -> 0 | Q17: =COUNTIFS('스위칭 연동 Switching'!$E$5:$E$400,"글로벌 · Global",'스위칭 연동 Switching'!$B$5:$B$400,"<>Live",'스위칭 연동 Switching'!$D$5:$D$400,"") -> 0 | R17: =COUNTIFS('서드파티 연동 3rd Party'!$E$5:$E$399,"글로벌 · Global",'서드파티 연동 3rd Party'!$B$5:$B$399,"<>Live",'서드파티 연동 3rd Party'!$D$5:$D$399,"") -> 0 | S17: =COUNTIFS('우리가 공급사 OMH Supply'!$E$5:$E$399,"글로벌 · Global",'우리가 공급사 OMH Supply'!$B$5:$B$399,"<>Live",'우리가 공급사 OMH Supply'!$D$5:$D$399,"") -> 1 | T17: =COUNTIFS('상호연동 Two-way'!$E$5:$E$400,"글로벌 · Global",'상호연동 Two-way'!$B$5:$B$400,"<>Live",'상호연동 Two-way'!$D$5:$D$400,"") -> 0 | U17: =SUM(P17:T17) -> 1
O18: 합계 · Total | P18: =SUM(P10:P17) -> 3 | Q18: =SUM(Q10:Q17) -> 16 | R18: =SUM(R10:R17) -> 4 | S18: =SUM(S10:S17) -> 62 | T18: =SUM(T10:T17) -> 16 | U18: =SUM(U10:U17) -> 101
O20: 담당별 진행 중 건수 · Open items by owner
O21: 담당 · Owner | P21: 스위칭 업체 Switch vendors | Q21: 스위칭 연동 Switching | R21: 서드파티 연동 3rd Party | S21: 우리가 공급사 OMH Supply | T21: 상호연동 Two-way | U21: 합계 Total | V21: 60일+ 정체 Stalled 60d+ | W21: 체이스 지연·필요 Chase overdue/needed
O22: Grace | P22: =COUNTIFS('스위칭 업체 Switch vendors'!$P$5:$P$400,$O22,'스위칭 업체 Switch vendors'!$B$5:$B$400,"<>Live",'스위칭 업체 Switch vendors'!$D$5:$D$400,"") -> 0 | Q22: =COUNTIFS('스위칭 연동 Switching'!$M$5:$M$400,$O22,'스위칭 연동 Switching'!$B$5:$B$400,"<>Live",'스위칭 연동 Switching'!$D$5:$D$400,"") -> 1 | R22: =COUNTIFS('서드파티 연동 3rd Party'!$M$5:$M$399,$O22,'서드파티 연동 3rd Party'!$B$5:$B$399,"<>Live",'서드파티 연동 3rd Party'!$D$5:$D$399,"") -> 0 | S22: =COUNTIFS('우리가 공급사 OMH Supply'!$M$5:$M$399,$O22,'우리가 공급사 OMH Supply'!$B$5:$B$399,"<>Live",'우리가 공급사 OMH Supply'!$D$5:$D$399,"") -> 22 | T22: =COUNTIFS('상호연동 Two-way'!$P$5:$P$400,$O22,'상호연동 Two-way'!$B$5:$B$400,"<>Live",'상호연동 Two-way'!$D$5:$D$400,"") -> 1 | U22: =SUM(P22:T22) -> 24 | V22: =COUNTIFS('스위칭 업체 Switch vendors'!$P$5:$P$400,$O22,'스위칭 업체 Switch vendors'!$V$5:$V$400,"Stalled 60d+")+COUNTIFS('스위칭 업체 Switch vendors'!$P$5:$P$400,$O22,'스위칭 업체 Switch vendors'!$V$5:$V$400,"Stalled 90d+")+COUNTIFS('스위칭 연동 Switching'!$M$5:$M$400,$O22,'스위칭 연동 Switching'!$S$5:$S$400,"Stalled 60d+")+COUNTIFS('스위칭 연동 Switching'!$M$5:$M$400,$O22,'스위칭 연동 Switching'!$S$5:$S$400,"Stalled 90d+")+COUNTIFS('서드파티 연동 3rd Party'!$M$5:$M$399,$O22,'서드파티 연동 3rd Party'!$S$5:$S$399,"Stalled 60d+")+COUNTIFS('서드파티 연동 3rd Party'!$M$5:$M$399,$O22,'서드파티 연동 3rd Party'!$S$5:$S$399,"Stalled 90d+")+COUNTIFS('우리가 공급사 OMH Supply'!$M$5:$M$399,$O22,'우리가 공급사 OMH Supply'!$S$5:$S$399,"Stalled 60d+")+COUNTIFS('우리가 공급사 OMH Supply'!$M$5:$M$399,$O22,'우리가 공급사 OMH Supply'!$S$5:$S$399,"Stalled 90d+")+COUNTIFS('상호연동 Two-way'!$P$5:$P$400,$O22,'상호연동 Two-way'!$V$5:$V$400,"Stalled 60d+")+COUNTIFS('상호연동 Two-way'!$P$5:$P$400,$O22,'상호연동 Two-way'!$V$5:$V$400,"Stalled 90d+") -> 7 | W22: =COUNTIFS('스위칭 업체 Switch vendors'!$P$5:$P$400,$O22,'스위칭 업체 Switch vendors'!$AC$5:$AC$400,"Chase Overdue")+COUNTIFS('스위칭 업체 Switch vendors'!$P$5:$P$400,$O22,'스위칭 업체 Switch vendors'!$AC$5:$AC$400,"Chase Needed")+COUNTIFS('스위칭 연동 Switching'!$M$5:$M$400,$O22,'스위칭 연동 Switching'!$Z$5:$Z$400,"Chase Overdue")+COUNTIFS('스위칭 연동 Switching'!$M$5:$M$400,$O22,'스위칭 연동 Switching'!$Z$5:$Z$400,"Chase Needed")+COUNTIFS('서드파티 연동 3rd Party'!$M$5:$M$399,$O22,'서드파티 연동 3rd Party'!$Z$5:$Z$399,"Chase Overdue")+COUNTIFS('서드파티 연동 3rd Party'!$M$5:$M$399,$O22,'서드파티 연동 3rd Party'!$Z$5:$Z$399,"Chase Needed")+COUNTIFS('우리가 공급사 OMH Supply'!$M$5:$M$399,$O22,'우리가 공급사 OMH Supply'!$Z$5:$Z$399,"Chase Overdue")+COUNTIFS('우리가 공급사 OMH Supply'!$M$5:$M$399,$O22,'우리가 공급사 OMH Supply'!$Z$5:$Z$399,"Chase Needed")+COUNTIFS('상호연동 Two-way'!$P$5:$P$400,$O22,'상호연동 Two-way'!$AC$5:$AC$400,"Chase Overdue")+COUNTIFS('상호연동 Two-way'!$P$5:$P$400,$O22,'상호연동 Two-way'!$AC$5:$AC$400,"Chase Needed") -> 11
O23: Aiden (지역 공백 · interim) | P23: =COUNTIFS('스위칭 업체 Switch vendors'!$P$5:$P$400,$O23,'스위칭 업체 Switch vendors'!$B$5:$B$400,"<>Live",'스위칭 업체 Switch vendors'!$D$5:$D$400,"") -> 0 | Q23: =COUNTIFS('스위칭 연동 Switching'!$M$5:$M$400,$O23,'스위칭 연동 Switching'!$B$5:$B$400,"<>Live",'스위칭 연동 Switching'!$D$5:$D$400,"") -> 4 | R23: =COUNTIFS('서드파티 연동 3rd Party'!$M$5:$M$399,$O23,'서드파티 연동 3rd Party'!$B$5:$B$399,"<>Live",'서드파티 연동 3rd Party'!$D$5:$D$399,"") -> 0 | S23: =COUNTIFS('우리가 공급사 OMH Supply'!$M$5:$M$399,$O23,'우리가 공급사 OMH Supply'!$B$5:$B$399,"<>Live",'우리가 공급사 OMH Supply'!$D$5:$D$399,"") -> 30 | T23: =COUNTIFS('상호연동 Two-way'!$P$5:$P$400,$O23,'상호연동 Two-way'!$B$5:$B$400,"<>Live",'상호연동 Two-way'!$D$5:$D$400,"") -> 7 | U23: =SUM(P23:T23) -> 41 | V23: =COUNTIFS('스위칭 업체 Switch vendors'!$P$5:$P$400,$O23,'스위칭 업체 Switch vendors'!$V$5:$V$400,"Stalled 60d+")+COUNTIFS('스위칭 업체 Switch vendors'!$P$5:$P$400,$O23,'스위칭 업체 Switch vendors'!$V$5:$V$400,"Stalled 90d+")+COUNTIFS('스위칭 연동 Switching'!$M$5:$M$400,$O23,'스위칭 연동 Switching'!$S$5:$S$400,"Stalled 60d+")+COUNTIFS('스위칭 연동 Switching'!$M$5:$M$400,$O23,'스위칭 연동 Switching'!$S$5:$S$400,"Stalled 90d+")+COUNTIFS('서드파티 연동 3rd Party'!$M$5:$M$399,$O23,'서드파티 연동 3rd Party'!$S$5:$S$399,"Stalled 60d+")+COUNTIFS('서드파티 연동 3rd Party'!$M$5:$M$399,$O23,'서드파티 연동 3rd Party'!$S$5:$S$399,"Stalled 90d+")+COUNTIFS('우리가 공급사 OMH Supply'!$M$5:$M$399,$O23,'우리가 공급사 OMH Supply'!$S$5:$S$399,"Stalled 60d+")+COUNTIFS('우리가 공급사 OMH Supply'!$M$5:$M$399,$O23,'우리가 공급사 OMH Supply'!$S$5:$S$399,"Stalled 90d+")+COUNTIFS('상호연동 Two-way'!$P$5:$P$400,$O23,'상호연동 Two-way'!$V$5:$V$400,"Stalled 60d+")+COUNTIFS('상호연동 Two-way'!$P$5:$P$400,$O23,'상호연동 Two-way'!$V$5:$V$400,"Stalled 90d+") -> 5 | W23: =COUNTIFS('스위칭 업체 Switch vendors'!$P$5:$P$400,$O23,'스위칭 업체 Switch vendors'!$AC$5:$AC$400,"Chase Overdue")+COUNTIFS('스위칭 업체 Switch vendors'!$P$5:$P$400,$O23,'스위칭 업체 Switch vendors'!$AC$5:$AC$400,"Chase Needed")+COUNTIFS('스위칭 연동 Switching'!$M$5:$M$400,$O23,'스위칭 연동 Switching'!$Z$5:$Z$400,"Chase Overdue")+COUNTIFS('스위칭 연동 Switching'!$M$5:$M$400,$O23,'스위칭 연동 Switching'!$Z$5:$Z$400,"Chase Needed")+COUNTIFS('서드파티 연동 3rd Party'!$M$5:$M$399,$O23,'서드파티 연동 3rd Party'!$Z$5:$Z$399,"Chase Overdue")+COUNTIFS('서드파티 연동 3rd Party'!$M$5:$M$399,$O23,'서드파티 연동 3rd Party'!$Z$5:$Z$399,"Chase Needed")+COUNTIFS('우리가 공급사 OMH Supply'!$M$5:$M$399,$O23,'우리가 공급사 OMH Supply'!$Z$5:$Z$399,"Chase Overdue")+COUNTIFS('우리가 공급사 OMH Supply'!$M$5:$M$399,$O23,'우리가 공급사 OMH Supply'!$Z$5:$Z$399,"Chase Needed")+COUNTIFS('상호연동 Two-way'!$P$5:$P$400,$O23,'상호연동 Two-way'!$AC$5:$AC$400,"Chase Overdue")+COUNTIFS('상호연동 Two-way'!$P$5:$P$400,$O23,'상호연동 Two-way'!$AC$5:$AC$400,"Chase Needed") -> 23
O24: GSM: Aiden → Jane (Dec~) | P24: =COUNTIFS('스위칭 업체 Switch vendors'!$P$5:$P$400,$O24,'스위칭 업체 Switch vendors'!$B$5:$B$400,"<>Live",'스위칭 업체 Switch vendors'!$D$5:$D$400,"") -> 3 | Q24: =COUNTIFS('스위칭 연동 Switching'!$M$5:$M$400,$O24,'스위칭 연동 Switching'!$B$5:$B$400,"<>Live",'스위칭 연동 Switching'!$D$5:$D$400,"") -> 10 | R24: =COUNTIFS('서드파티 연동 3rd Party'!$M$5:$M$399,$O24,'서드파티 연동 3rd Party'!$B$5:$B$399,"<>Live",'서드파티 연동 3rd Party'!$D$5:$D$399,"") -> 0 | S24: =COUNTIFS('우리가 공급사 OMH Supply'!$M$5:$M$399,$O24,'우리가 공급사 OMH Supply'!$B$5:$B$399,"<>Live",'우리가 공급사 OMH Supply'!$D$5:$D$399,"") -> 0 | T24: =COUNTIFS('상호연동 Two-way'!$P$5:$P$400,$O24,'상호연동 Two-way'!$B$5:$B$400,"<>Live",'상호연동 Two-way'!$D$5:$D$400,"") -> 8 | U24: =SUM(P24:T24) -> 21 | V24: =COUNTIFS('스위칭 업체 Switch vendors'!$P$5:$P$400,$O24,'스위칭 업체 Switch vendors'!$V$5:$V$400,"Stalled 60d+")+COUNTIFS('스위칭 업체 Switch vendors'!$P$5:$P$400,$O24,'스위칭 업체 Switch vendors'!$V$5:$V$400,"Stalled 90d+")+COUNTIFS('스위칭 연동 Switching'!$M$5:$M$400,$O24,'스위칭 연동 Switching'!$S$5:$S$400,"Stalled 60d+")+COUNTIFS('스위칭 연동 Switching'!$M$5:$M$400,$O24,'스위칭 연동 Switching'!$S$5:$S$400,"Stalled 90d+")+COUNTIFS('서드파티 연동 3rd Party'!$M$5:$M$399,$O24,'서드파티 연동 3rd Party'!$S$5:$S$399,"Stalled 60d+")+COUNTIFS('서드파티 연동 3rd Party'!$M$5:$M$399,$O24,'서드파티 연동 3rd Party'!$S$5:$S$399,"Stalled 90d+")+COUNTIFS('우리가 공급사 OMH Supply'!$M$5:$M$399,$O24,'우리가 공급사 OMH Supply'!$S$5:$S$399,"Stalled 60d+")+COUNTIFS('우리가 공급사 OMH Supply'!$M$5:$M$399,$O24,'우리가 공급사 OMH Supply'!$S$5:$S$399,"Stalled 90d+")+COUNTIFS('상호연동 Two-way'!$P$5:$P$400,$O24,'상호연동 Two-way'!$V$5:$V$400,"Stalled 60d+")+COUNTIFS('상호연동 Two-way'!$P$5:$P$400,$O24,'상호연동 Two-way'!$V$5:$V$400,"Stalled 90d+") -> 1 | W24: =COUNTIFS('스위칭 업체 Switch vendors'!$P$5:$P$400,$O24,'스위칭 업체 Switch vendors'!$AC$5:$AC$400,"Chase Overdue")+COUNTIFS('스위칭 업체 Switch vendors'!$P$5:$P$400,$O24,'스위칭 업체 Switch vendors'!$AC$5:$AC$400,"Chase Needed")+COUNTIFS('스위칭 연동 Switching'!$M$5:$M$400,$O24,'스위칭 연동 Switching'!$Z$5:$Z$400,"Chase Overdue")+COUNTIFS('스위칭 연동 Switching'!$M$5:$M$400,$O24,'스위칭 연동 Switching'!$Z$5:$Z$400,"Chase Needed")+COUNTIFS('서드파티 연동 3rd Party'!$M$5:$M$399,$O24,'서드파티 연동 3rd Party'!$Z$5:$Z$399,"Chase Overdue")+COUNTIFS('서드파티 연동 3rd Party'!$M$5:$M$399,$O24,'서드파티 연동 3rd Party'!$Z$5:$Z$399,"Chase Needed")+COUNTIFS('우리가 공급사 OMH Supply'!$M$5:$M$399,$O24,'우리가 공급사 OMH Supply'!$Z$5:$Z$399,"Chase Overdue")+COUNTIFS('우리가 공급사 OMH Supply'!$M$5:$M$399,$O24,'우리가 공급사 OMH Supply'!$Z$5:$Z$399,"Chase Needed")+COUNTIFS('상호연동 Two-way'!$P$5:$P$400,$O24,'상호연동 Two-way'!$AC$5:$AC$400,"Chase Overdue")+COUNTIFS('상호연동 Two-way'!$P$5:$P$400,$O24,'상호연동 Two-way'!$AC$5:$AC$400,"Chase Needed") -> 9
O25: Jane | P25: =COUNTIFS('스위칭 업체 Switch vendors'!$P$5:$P$400,$O25,'스위칭 업체 Switch vendors'!$B$5:$B$400,"<>Live",'스위칭 업체 Switch vendors'!$D$5:$D$400,"") -> 0 | Q25: =COUNTIFS('스위칭 연동 Switching'!$M$5:$M$400,$O25,'스위칭 연동 Switching'!$B$5:$B$400,"<>Live",'스위칭 연동 Switching'!$D$5:$D$400,"") -> 0 | R25: =COUNTIFS('서드파티 연동 3rd Party'!$M$5:$M$399,$O25,'서드파티 연동 3rd Party'!$B$5:$B$399,"<>Live",'서드파티 연동 3rd Party'!$D$5:$D$399,"") -> 0 | S25: =COUNTIFS('우리가 공급사 OMH Supply'!$M$5:$M$399,$O25,'우리가 공급사 OMH Supply'!$B$5:$B$399,"<>Live",'우리가 공급사 OMH Supply'!$D$5:$D$399,"") -> 8 | T25: =COUNTIFS('상호연동 Two-way'!$P$5:$P$400,$O25,'상호연동 Two-way'!$B$5:$B$400,"<>Live",'상호연동 Two-way'!$D$5:$D$400,"") -> 0 | U25: =SUM(P25:T25) -> 8 | V25: =COUNTIFS('스위칭 업체 Switch vendors'!$P$5:$P$400,$O25,'스위칭 업체 Switch vendors'!$V$5:$V$400,"Stalled 60d+")+COUNTIFS('스위칭 업체 Switch vendors'!$P$5:$P$400,$O25,'스위칭 업체 Switch vendors'!$V$5:$V$400,"Stalled 90d+")+COUNTIFS('스위칭 연동 Switching'!$M$5:$M$400,$O25,'스위칭 연동 Switching'!$S$5:$S$400,"Stalled 60d+")+COUNTIFS('스위칭 연동 Switching'!$M$5:$M$400,$O25,'스위칭 연동 Switching'!$S$5:$S$400,"Stalled 90d+")+COUNTIFS('서드파티 연동 3rd Party'!$M$5:$M$399,$O25,'서드파티 연동 3rd Party'!$S$5:$S$399,"Stalled 60d+")+COUNTIFS('서드파티 연동 3rd Party'!$M$5:$M$399,$O25,'서드파티 연동 3rd Party'!$S$5:$S$399,"Stalled 90d+")+COUNTIFS('우리가 공급사 OMH Supply'!$M$5:$M$399,$O25,'우리가 공급사 OMH Supply'!$S$5:$S$399,"Stalled 60d+")+COUNTIFS('우리가 공급사 OMH Supply'!$M$5:$M$399,$O25,'우리가 공급사 OMH Supply'!$S$5:$S$399,"Stalled 90d+")+COUNTIFS('상호연동 Two-way'!$P$5:$P$400,$O25,'상호연동 Two-way'!$V$5:$V$400,"Stalled 60d+")+COUNTIFS('상호연동 Two-way'!$P$5:$P$400,$O25,'상호연동 Two-way'!$V$5:$V$400,"Stalled 90d+") -> 1 | W25: =COUNTIFS('스위칭 업체 Switch vendors'!$P$5:$P$400,$O25,'스위칭 업체 Switch vendors'!$AC$5:$AC$400,"Chase Overdue")+COUNTIFS('스위칭 업체 Switch vendors'!$P$5:$P$400,$O25,'스위칭 업체 Switch vendors'!$AC$5:$AC$400,"Chase Needed")+COUNTIFS('스위칭 연동 Switching'!$M$5:$M$400,$O25,'스위칭 연동 Switching'!$Z$5:$Z$400,"Chase Overdue")+COUNTIFS('스위칭 연동 Switching'!$M$5:$M$400,$O25,'스위칭 연동 Switching'!$Z$5:$Z$400,"Chase Needed")+COUNTIFS('서드파티 연동 3rd Party'!$M$5:$M$399,$O25,'서드파티 연동 3rd Party'!$Z$5:$Z$399,"Chase Overdue")+COUNTIFS('서드파티 연동 3rd Party'!$M$5:$M$399,$O25,'서드파티 연동 3rd Party'!$Z$5:$Z$399,"Chase Needed")+COUNTIFS('우리가 공급사 OMH Supply'!$M$5:$M$399,$O25,'우리가 공급사 OMH Supply'!$Z$5:$Z$399,"Chase Overdue")+COUNTIFS('우리가 공급사 OMH Supply'!$M$5:$M$399,$O25,'우리가 공급사 OMH Supply'!$Z$5:$Z$399,"Chase Needed")+COUNTIFS('상호연동 Two-way'!$P$5:$P$400,$O25,'상호연동 Two-way'!$AC$5:$AC$400,"Chase Overdue")+COUNTIFS('상호연동 Two-way'!$P$5:$P$400,$O25,'상호연동 Two-way'!$AC$5:$AC$400,"Chase Needed") -> 2
O26: Aiden (일본 · interim JP) | P26: =COUNTIFS('스위칭 업체 Switch vendors'!$P$5:$P$400,$O26,'스위칭 업체 Switch vendors'!$B$5:$B$400,"<>Live",'스위칭 업체 Switch vendors'!$D$5:$D$400,"") -> 0 | Q26: =COUNTIFS('스위칭 연동 Switching'!$M$5:$M$400,$O26,'스위칭 연동 Switching'!$B$5:$B$400,"<>Live",'스위칭 연동 Switching'!$D$5:$D$400,"") -> 1 | R26: =COUNTIFS('서드파티 연동 3rd Party'!$M$5:$M$399,$O26,'서드파티 연동 3rd Party'!$B$5:$B$399,"<>Live",'서드파티 연동 3rd Party'!$D$5:$D$399,"") -> 0 | S26: =COUNTIFS('우리가 공급사 OMH Supply'!$M$5:$M$399,$O26,'우리가 공급사 OMH Supply'!$B$5:$B$399,"<>Live",'우리가 공급사 OMH Supply'!$D$5:$D$399,"") -> 2 | T26: =COUNTIFS('상호연동 Two-way'!$P$5:$P$400,$O26,'상호연동 Two-way'!$B$5:$B$400,"<>Live",'상호연동 Two-way'!$D$5:$D$400,"") -> 0 | U26: =SUM(P26:T26) -> 3 | V26: =COUNTIFS('스위칭 업체 Switch vendors'!$P$5:$P$400,$O26,'스위칭 업체 Switch vendors'!$V$5:$V$400,"Stalled 60d+")+COUNTIFS('스위칭 업체 Switch vendors'!$P$5:$P$400,$O26,'스위칭 업체 Switch vendors'!$V$5:$V$400,"Stalled 90d+")+COUNTIFS('스위칭 연동 Switching'!$M$5:$M$400,$O26,'스위칭 연동 Switching'!$S$5:$S$400,"Stalled 60d+")+COUNTIFS('스위칭 연동 Switching'!$M$5:$M$400,$O26,'스위칭 연동 Switching'!$S$5:$S$400,"Stalled 90d+")+COUNTIFS('서드파티 연동 3rd Party'!$M$5:$M$399,$O26,'서드파티 연동 3rd Party'!$S$5:$S$399,"Stalled 60d+")+COUNTIFS('서드파티 연동 3rd Party'!$M$5:$M$399,$O26,'서드파티 연동 3rd Party'!$S$5:$S$399,"Stalled 90d+")+COUNTIFS('우리가 공급사 OMH Supply'!$M$5:$M$399,$O26,'우리가 공급사 OMH Supply'!$S$5:$S$399,"Stalled 60d+")+COUNTIFS('우리가 공급사 OMH Supply'!$M$5:$M$399,$O26,'우리가 공급사 OMH Supply'!$S$5:$S$399,"Stalled 90d+")+COUNTIFS('상호연동 Two-way'!$P$5:$P$400,$O26,'상호연동 Two-way'!$V$5:$V$400,"Stalled 60d+")+COUNTIFS('상호연동 Two-way'!$P$5:$P$400,$O26,'상호연동 Two-way'!$V$5:$V$400,"Stalled 90d+") -> 0 | W26: =COUNTIFS('스위칭 업체 Switch vendors'!$P$5:$P$400,$O26,'스위칭 업체 Switch vendors'!$AC$5:$AC$400,"Chase Overdue")+COUNTIFS('스위칭 업체 Switch vendors'!$P$5:$P$400,$O26,'스위칭 업체 Switch vendors'!$AC$5:$AC$400,"Chase Needed")+COUNTIFS('스위칭 연동 Switching'!$M$5:$M$400,$O26,'스위칭 연동 Switching'!$Z$5:$Z$400,"Chase Overdue")+COUNTIFS('스위칭 연동 Switching'!$M$5:$M$400,$O26,'스위칭 연동 Switching'!$Z$5:$Z$400,"Chase Needed")+COUNTIFS('서드파티 연동 3rd Party'!$M$5:$M$399,$O26,'서드파티 연동 3rd Party'!$Z$5:$Z$399,"Chase Overdue")+COUNTIFS('서드파티 연동 3rd Party'!$M$5:$M$399,$O26,'서드파티 연동 3rd Party'!$Z$5:$Z$399,"Chase Needed")+COUNTIFS('우리가 공급사 OMH Supply'!$M$5:$M$399,$O26,'우리가 공급사 OMH Supply'!$Z$5:$Z$399,"Chase Overdue")+COUNTIFS('우리가 공급사 OMH Supply'!$M$5:$M$399,$O26,'우리가 공급사 OMH Supply'!$Z$5:$Z$399,"Chase Needed")+COUNTIFS('상호연동 Two-way'!$P$5:$P$400,$O26,'상호연동 Two-way'!$AC$5:$AC$400,"Chase Overdue")+COUNTIFS('상호연동 Two-way'!$P$5:$P$400,$O26,'상호연동 Two-way'!$AC$5:$AC$400,"Chase Needed") -> 0
O27: SCM by country · Aiden | P27: =COUNTIFS('스위칭 업체 Switch vendors'!$P$5:$P$400,$O27,'스위칭 업체 Switch vendors'!$B$5:$B$400,"<>Live",'스위칭 업체 Switch vendors'!$D$5:$D$400,"") -> 0 | Q27: =COUNTIFS('스위칭 연동 Switching'!$M$5:$M$400,$O27,'스위칭 연동 Switching'!$B$5:$B$400,"<>Live",'스위칭 연동 Switching'!$D$5:$D$400,"") -> 0 | R27: =COUNTIFS('서드파티 연동 3rd Party'!$M$5:$M$399,$O27,'서드파티 연동 3rd Party'!$B$5:$B$399,"<>Live",'서드파티 연동 3rd Party'!$D$5:$D$399,"") -> 0 | S27: =COUNTIFS('우리가 공급사 OMH Supply'!$M$5:$M$399,$O27,'우리가 공급사 OMH Supply'!$B$5:$B$399,"<>Live",'우리가 공급사 OMH Supply'!$D$5:$D$399,"") -> 0 | T27: =COUNTIFS('상호연동 Two-way'!$P$5:$P$400,$O27,'상호연동 Two-way'!$B$5:$B$400,"<>Live",'상호연동 Two-way'!$D$5:$D$400,"") -> 0 | U27: =SUM(P27:T27) -> 0 | V27: =COUNTIFS('스위칭 업체 Switch vendors'!$P$5:$P$400,$O27,'스위칭 업체 Switch vendors'!$V$5:$V$400,"Stalled 60d+")+COUNTIFS('스위칭 업체 Switch vendors'!$P$5:$P$400,$O27,'스위칭 업체 Switch vendors'!$V$5:$V$400,"Stalled 90d+")+COUNTIFS('스위칭 연동 Switching'!$M$5:$M$400,$O27,'스위칭 연동 Switching'!$S$5:$S$400,"Stalled 60d+")+COUNTIFS('스위칭 연동 Switching'!$M$5:$M$400,$O27,'스위칭 연동 Switching'!$S$5:$S$400,"Stalled 90d+")+COUNTIFS('서드파티 연동 3rd Party'!$M$5:$M$399,$O27,'서드파티 연동 3rd Party'!$S$5:$S$399,"Stalled 60d+")+COUNTIFS('서드파티 연동 3rd Party'!$M$5:$M$399,$O27,'서드파티 연동 3rd Party'!$S$5:$S$399,"Stalled 90d+")+COUNTIFS('우리가 공급사 OMH Supply'!$M$5:$M$399,$O27,'우리가 공급사 OMH Supply'!$S$5:$S$399,"Stalled 60d+")+COUNTIFS('우리가 공급사 OMH Supply'!$M$5:$M$399,$O27,'우리가 공급사 OMH Supply'!$S$5:$S$399,"Stalled 90d+")+COUNTIFS('상호연동 Two-way'!$P$5:$P$400,$O27,'상호연동 Two-way'!$V$5:$V$400,"Stalled 60d+")+COUNTIFS('상호연동 Two-way'!$P$5:$P$400,$O27,'상호연동 Two-way'!$V$5:$V$400,"Stalled 90d+") -> 0 | W27: =COUNTIFS('스위칭 업체 Switch vendors'!$P$5:$P$400,$O27,'스위칭 업체 Switch vendors'!$AC$5:$AC$400,"Chase Overdue")+COUNTIFS('스위칭 업체 Switch vendors'!$P$5:$P$400,$O27,'스위칭 업체 Switch vendors'!$AC$5:$AC$400,"Chase Needed")+COUNTIFS('스위칭 연동 Switching'!$M$5:$M$400,$O27,'스위칭 연동 Switching'!$Z$5:$Z$400,"Chase Overdue")+COUNTIFS('스위칭 연동 Switching'!$M$5:$M$400,$O27,'스위칭 연동 Switching'!$Z$5:$Z$400,"Chase Needed")+COUNTIFS('서드파티 연동 3rd Party'!$M$5:$M$399,$O27,'서드파티 연동 3rd Party'!$Z$5:$Z$399,"Chase Overdue")+COUNTIFS('서드파티 연동 3rd Party'!$M$5:$M$399,$O27,'서드파티 연동 3rd Party'!$Z$5:$Z$399,"Chase Needed")+COUNTIFS('우리가 공급사 OMH Supply'!$M$5:$M$399,$O27,'우리가 공급사 OMH Supply'!$Z$5:$Z$399,"Chase Overdue")+COUNTIFS('우리가 공급사 OMH Supply'!$M$5:$M$399,$O27,'우리가 공급사 OMH Supply'!$Z$5:$Z$399,"Chase Needed")+COUNTIFS('상호연동 Two-way'!$P$5:$P$400,$O27,'상호연동 Two-way'!$AC$5:$AC$400,"Chase Overdue")+COUNTIFS('상호연동 Two-way'!$P$5:$P$400,$O27,'상호연동 Two-way'!$AC$5:$AC$400,"Chase Needed") -> 0
O28: Aiden | P28: =COUNTIFS('스위칭 업체 Switch vendors'!$P$5:$P$400,$O28,'스위칭 업체 Switch vendors'!$B$5:$B$400,"<>Live",'스위칭 업체 Switch vendors'!$D$5:$D$400,"") -> 0 | Q28: =COUNTIFS('스위칭 연동 Switching'!$M$5:$M$400,$O28,'스위칭 연동 Switching'!$B$5:$B$400,"<>Live",'스위칭 연동 Switching'!$D$5:$D$400,"") -> 0 | R28: =COUNTIFS('서드파티 연동 3rd Party'!$M$5:$M$399,$O28,'서드파티 연동 3rd Party'!$B$5:$B$399,"<>Live",'서드파티 연동 3rd Party'!$D$5:$D$399,"") -> 0 | S28: =COUNTIFS('우리가 공급사 OMH Supply'!$M$5:$M$399,$O28,'우리가 공급사 OMH Supply'!$B$5:$B$399,"<>Live",'우리가 공급사 OMH Supply'!$D$5:$D$399,"") -> 0 | T28: =COUNTIFS('상호연동 Two-way'!$P$5:$P$400,$O28,'상호연동 Two-way'!$B$5:$B$400,"<>Live",'상호연동 Two-way'!$D$5:$D$400,"") -> 0 | U28: =SUM(P28:T28) -> 0 | V28: =COUNTIFS('스위칭 업체 Switch vendors'!$P$5:$P$400,$O28,'스위칭 업체 Switch vendors'!$V$5:$V$400,"Stalled 60d+")+COUNTIFS('스위칭 업체 Switch vendors'!$P$5:$P$400,$O28,'스위칭 업체 Switch vendors'!$V$5:$V$400,"Stalled 90d+")+COUNTIFS('스위칭 연동 Switching'!$M$5:$M$400,$O28,'스위칭 연동 Switching'!$S$5:$S$400,"Stalled 60d+")+COUNTIFS('스위칭 연동 Switching'!$M$5:$M$400,$O28,'스위칭 연동 Switching'!$S$5:$S$400,"Stalled 90d+")+COUNTIFS('서드파티 연동 3rd Party'!$M$5:$M$399,$O28,'서드파티 연동 3rd Party'!$S$5:$S$399,"Stalled 60d+")+COUNTIFS('서드파티 연동 3rd Party'!$M$5:$M$399,$O28,'서드파티 연동 3rd Party'!$S$5:$S$399,"Stalled 90d+")+COUNTIFS('우리가 공급사 OMH Supply'!$M$5:$M$399,$O28,'우리가 공급사 OMH Supply'!$S$5:$S$399,"Stalled 60d+")+COUNTIFS('우리가 공급사 OMH Supply'!$M$5:$M$399,$O28,'우리가 공급사 OMH Supply'!$S$5:$S$399,"Stalled 90d+")+COUNTIFS('상호연동 Two-way'!$P$5:$P$400,$O28,'상호연동 Two-way'!$V$5:$V$400,"Stalled 60d+")+COUNTIFS('상호연동 Two-way'!$P$5:$P$400,$O28,'상호연동 Two-way'!$V$5:$V$400,"Stalled 90d+") -> 0 | W28: =COUNTIFS('스위칭 업체 Switch vendors'!$P$5:$P$400,$O28,'스위칭 업체 Switch vendors'!$AC$5:$AC$400,"Chase Overdue")+COUNTIFS('스위칭 업체 Switch vendors'!$P$5:$P$400,$O28,'스위칭 업체 Switch vendors'!$AC$5:$AC$400,"Chase Needed")+COUNTIFS('스위칭 연동 Switching'!$M$5:$M$400,$O28,'스위칭 연동 Switching'!$Z$5:$Z$400,"Chase Overdue")+COUNTIFS('스위칭 연동 Switching'!$M$5:$M$400,$O28,'스위칭 연동 Switching'!$Z$5:$Z$400,"Chase Needed")+COUNTIFS('서드파티 연동 3rd Party'!$M$5:$M$399,$O28,'서드파티 연동 3rd Party'!$Z$5:$Z$399,"Chase Overdue")+COUNTIFS('서드파티 연동 3rd Party'!$M$5:$M$399,$O28,'서드파티 연동 3rd Party'!$Z$5:$Z$399,"Chase Needed")+COUNTIFS('우리가 공급사 OMH Supply'!$M$5:$M$399,$O28,'우리가 공급사 OMH Supply'!$Z$5:$Z$399,"Chase Overdue")+COUNTIFS('우리가 공급사 OMH Supply'!$M$5:$M$399,$O28,'우리가 공급사 OMH Supply'!$Z$5:$Z$399,"Chase Needed")+COUNTIFS('상호연동 Two-way'!$P$5:$P$400,$O28,'상호연동 Two-way'!$AC$5:$AC$400,"Chase Overdue")+COUNTIFS('상호연동 Two-way'!$P$5:$P$400,$O28,'상호연동 Two-way'!$AC$5:$AC$400,"Chase Needed") -> 0
B35: 지금 챙길 것 — 60일 이상 정체 (2026-10-19 스냅샷) · Watch list — stalled 60+ days (snapshot 19 Oct; use the 'Delay check' filter for live data)
B36: 카테고리 Category | C36: 프로젝트 Project | D36: 지역 Region | E36: 담당 Owner | F36: 진행률 Progress | G36: 경과일 Days | H36: 현황 · 다음 액션 Status · next action
B37: 우리가 공급사 OMH Supply | C37: Uone | D37: 중화권 · Greater China | E37: Grace | F37: 0.2 | G37: 406
B38: 스위칭 연동 Switching | C38: Lion Travel | D38: 중화권 · Greater China | E38: Grace | F38: 0.2 | G38: 402 | H38: Shiji 셀러 측 인터페이스 완료(10월 말~11월 초) 후 Shiji 경유 첫 채널 오픈 준비 — Shiji 폴더 TASKS #7(3자 미팅)과 연계 After Shiji seller-side interface is complete (late Oct–early Nov), prepare first channel launch via Shiji — link with Shiji folder TASKS #7 (three-party meeting)
B39: 우리가 공급사 OMH Supply | C39: Amerilink | D39: 중화권 · Greater China | E39: Grace | F39: 0.2 | G39: 357
B40: 우리가 공급사 OMH Supply | C40: Star Travel | D40: 중화권 · Greater China | E40: Grace | F40: 0.5 | G40: 321
B41: 상호연동 Two-way | C41: Chudu24 | D41: 동남아 · SE Asia | E41: GSM: Aiden → Jane (Dec~) | F41: 0.3 | G41: 313 | H41: API·2-way 제안 회신 체이스 + 탑셀링·피크 프로모션 공유 Chase reply on API/2-way proposal + share top-selling and peak promotions
B42: 우리가 공급사 OMH Supply | C42: Justgotrip | D42: 중화권 · Greater China | E42: Grace | F42: 0.2 | G42: 287
B43: 우리가 공급사 OMH Supply | C43: Gotadi - HN Branch | D43: 동남아 · SE Asia | E43: Aiden (지역 공백 · interim) | F43: 0.4 | G43: 102 | H43: 재가동 회신 2차 체이스 + OMH 측 개발 deliverable·ETA 확정 Second chase for re-engagement reply + confirm OMH-side development deliverables and ETA
B44: 상호연동 Two-way | C44: G2 Travel | D44: 유럽·미주 · Europe & Americas | E44: Aiden (지역 공백 · interim) | F44: 0.2 | G44: 101
B45: 상호연동 Two-way | C45: Tiket.com | D45: 동남아 · SE Asia | E45: Aiden (지역 공백 · interim) | F45: 0.2 | G45: 68 | H45: Celine 체이스 또는 Hold 결정 Chase Celine or decide to put on hold
B46: 상호연동 Two-way | C46: Tiket.com | D46: 동남아 · SE Asia | E46: Aiden (지역 공백 · interim) | F46: 0.2 | G46: 68 | H46: Celine 체이스 또는 Hold 결정 Chase Celine or decide to put on hold
B47: 우리가 공급사 OMH Supply | C47: Huamao | D47: 중화권 · Greater China | E47: Grace | F47: 0.5 | G47: 66 | H47: 개발 재개 확인 — 8/3 API 오류 해결 여부·인증 일정 Confirm development has resumed — whether the 3 Aug API error is resolved and certification schedule
B48: 우리가 공급사 OMH Supply | C48: Ziru (TMC) | D48: 중화권 · Greater China | E48: Grace | F48: 0.5 | G48: 66
B49: 우리가 공급사 OMH Supply | C49: Travelata(Vivatech) | D49: 중동·러시아 · ME & Russia | E49: Aiden (지역 공백 · interim) | F49: 0.5 | G49: 61 | H49: API 연동 진행(DEV·개발 일정·담당자·IP) 체이스 + 보증금 USD 20,000 입금 확인 Chase API integration progress (DEV, development schedule, contact person, IP) + confirm deposit of USD 20,000 received

Sheet 개발 간트 Dev Gantt
B1: 개발 진행 간트차트 · Dev Progress Gantt
B2: ="오늘 Today "&TEXT(TODAY(),"yyyy-mm-dd")&" · 주 단위 간트 · 날짜는 해당 주의 아무 날짜나 입력해도 그 주에 표시됩니다 · Weekly view – any date in the week works" -> 오늘 Today 2026-10-30 · 주 단위 간트 · 날짜는 해당 주의 아무 날짜나 입력해도 그 주에 표시됩니다 · Weekly view – any date in the week works
B4: 타임라인 시작일 Timeline start | E4: =EOMONTH(TODAY(),-2)+1 -> 46266 | F4: ← 이 날짜가 속한 주(월요일)부터 26주 표시 · Shows 26 weeks from this week | J4: 범례 Legend | M4: 개발중 | P4: 지연 | S4: 예정/완료 | V4: 라이브 주 | Y4: 이번 주
M5: In Dev | P5: Overdue | S5: Planned/Done | V5: Go-Live week | Y5: This week
B6: No. | C6: 업체명 Vendor | D6: 업체코드 Vendor Code | E6: 개발자 Developer | F6: 개발 시작일 Dev Start | G6: 완료 예정일 Dev End (plan) | H6: 라이브 일자 Go-Live | I6: 기간(주) Weeks | J6: 상태 Status | K6: =TEXT(K8,"yyyy-mm") -> 2026-08 | L6: =IF(MONTH(L8)<>MONTH(K8),TEXT(L8,"yyyy-mm"),"") -> 2026-09 | M6: =IF(MONTH(M8)<>MONTH(L8),TEXT(M8,"yyyy-mm"),"") | N6: =IF(MONTH(N8)<>MONTH(M8),TEXT(N8,"yyyy-mm"),"") | O6: =IF(MONTH(O8)<>MONTH(N8),TEXT(O8,"yyyy-mm"),"") | P6: =IF(MONTH(P8)<>MONTH(O8),TEXT(P8,"yyyy-mm"),"") -> 2026-10 | Q6: =IF(MONTH(Q8)<>MONTH(P8),TEXT(Q8,"yyyy-mm"),"") | R6: =IF(MONTH(R8)<>MONTH(Q8),TEXT(R8,"yyyy-mm"),"") | S6: =IF(MONTH(S8)<>MONTH(R8),TEXT(S8,"yyyy-mm"),"") | ... AJ6: =IF(MONTH(AJ8)<>MONTH(AI8),TEXT(AJ8,"yyyy-mm"),"")
K7: =INT((DAY(K8)-1)/7)+1&"주" -> 5주 | L7: =INT((DAY(L8)-1)/7)+1&"주" -> 1주 | M7: =INT((DAY(M8)-1)/7)+1&"주" -> 2주 | N7: =INT((DAY(N8)-1)/7)+1&"주" -> 3주 | O7: =INT((DAY(O8)-1)/7)+1&"주" -> 4주 | P7: =INT((DAY(P8)-1)/7)+1&"주" -> 1주 | Q7: =INT((DAY(Q8)-1)/7)+1&"주" -> 2주 | R7: =INT((DAY(R8)-1)/7)+1&"주" -> 3주 | ... AJ7: =INT((DAY(AJ8)-1)/7)+1&"주" -> 4주
K8: =$E$4-WEEKDAY($E$4,3) -> 46265 | L8: =K8+7 -> 46272 | M8: =L8+7 -> 46279 | N8: =M8+7 -> 46286 | O8: =N8+7 -> 46293 | P8: =O8+7 -> 46300 | Q8: =P8+7 -> 46307 | R8: =Q8+7 -> 46314 | S8: =R8+7 -> 46321 | ... AJ8: =AI8+7 -> 46440
B9: =IF(C9="","",ROW()-8) -> 1 | C9: test agency | E9: Aiden | F9: 46322 | G9: 46337 | H9: 46351 | I9: =IF(OR(F9="",G9=""),"",ROUNDUP((G9-F9+1)/7,0)) -> 3 | J9: =IF(C9="","",IF(AND(H9<>"",H9<=TODAY()),"라이브 Live",IF(F9="","미정 TBD",IF(TODAY()<F9,"예정 Planned",IF(AND(G9<>"",TODAY()>G9),"지연 Overdue","개발중 In Dev"))))) -> 개발중 In Dev
B10: =IF(C10="","",ROW()-8) -> 2 | C10: ABC Travel Service | E10: Tan | F10: 46357 | G10: 46386 | I10: =IF(OR(F10="",G10=""),"",ROUNDUP((G10-F10+1)/7,0)) -> 5 | J10: =IF(C10="","",IF(AND(H10<>"",H10<=TODAY()),"라이브 Live",IF(F10="","미정 TBD",IF(TODAY()<F10,"예정 Planned",IF(AND(G10<>"",TODAY()>G10),"지연 Overdue","개발중 In Dev"))))) -> 예정 Planned
B11: 3 | C11: STAYLAH | E11: Tan | F11: 46328 | G11: 46356 | I11: =IF(OR(F11="",G11=""),"",ROUNDUP((G11-F11+1)/7,0)) -> 5 | J11: =IF(C11="","",IF(AND(H11<>"",H11<=TODAY()),"라이브 Live",IF(F11="","미정 TBD",IF(TODAY()<F11,"예정 Planned",IF(AND(G11<>"",TODAY()>G11),"지연 Overdue","개발중 In Dev"))))) -> 예정 Planned
B12: 4 | C12: DiDi TMC | E12: Calvin | F12: 46371 | G12: 46402 | I12: =IF(OR(F12="",G12=""),"",ROUNDUP((G12-F12+1)/7,0)) -> 5 | J12: =IF(C12="","",IF(AND(H12<>"",H12<=TODAY()),"라이브 Live",IF(F12="","미정 TBD",IF(TODAY()<F12,"예정 Planned",IF(AND(G12<>"",TODAY()>G12),"지연 Overdue","개발중 In Dev"))))) -> 예정 Planned
B13: 5 | I13: =IF(OR(F13="",G13=""),"",ROUNDUP((G13-F13+1)/7,0)) | J13: =IF(C13="","",IF(AND(H13<>"",H13<=TODAY()),"라이브 Live",IF(F13="","미정 TBD",IF(TODAY()<F13,"예정 Planned",IF(AND(G13<>"",TODAY()>G13),"지연 Overdue","개발중 In Dev")))))
B14: 6 | I14: =IF(OR(F14="",G14=""),"",ROUNDUP((G14-F14+1)/7,0)) | J14: =IF(C14="","",IF(AND(H14<>"",H14<=TODAY()),"라이브 Live",IF(F14="","미정 TBD",IF(TODAY()<F14,"예정 Planned",IF(AND(G14<>"",TODAY()>G14),"지연 Overdue","개발중 In Dev")))))
B15: 7 | I15: =IF(OR(F15="",G15=""),"",ROUNDUP((G15-F15+1)/7,0)) | J15: =IF(C15="","",IF(AND(H15<>"",H15<=TODAY()),"라이브 Live",IF(F15="","미정 TBD",IF(TODAY()<F15,"예정 Planned",IF(AND(G15<>"",TODAY()>G15),"지연 Overdue","개발중 In Dev")))))
B16: 8 | I16: =IF(OR(F16="",G16=""),"",ROUNDUP((G16-F16+1)/7,0)) | J16: =IF(C16="","",IF(AND(H16<>"",H16<=TODAY()),"라이브 Live",IF(F16="","미정 TBD",IF(TODAY()<F16,"예정 Planned",IF(AND(G16<>"",TODAY()>G16),"지연 Overdue","개발중 In Dev")))))
B17: 9 | I17: =IF(OR(F17="",G17=""),"",ROUNDUP((G17-F17+1)/7,0)) | J17: =IF(C17="","",IF(AND(H17<>"",H17<=TODAY()),"라이브 Live",IF(F17="","미정 TBD",IF(TODAY()<F17,"예정 Planned",IF(AND(G17<>"",TODAY()>G17),"지연 Overdue","개발중 In Dev")))))
B18: 10 | I18: =IF(OR(F18="",G18=""),"",ROUNDUP((G18-F18+1)/7,0)) | J18: =IF(C18="","",IF(AND(H18<>"",H18<=TODAY()),"라이브 Live",IF(F18="","미정 TBD",IF(TODAY()<F18,"예정 Planned",IF(AND(G18<>"",TODAY()>G18),"지연 Overdue","개발중 In Dev")))))
B19: 11 | I19: =IF(OR(F19="",G19=""),"",ROUNDUP((G19-F19+1)/7,0)) | J19: =IF(C19="","",IF(AND(H19<>"",H19<=TODAY()),"라이브 Live",IF(F19="","미정 TBD",IF(TODAY()<F19,"예정 Planned",IF(AND(G19<>"",TODAY()>G19),"지연 Overdue","개발중 In Dev")))))
B20: =IF(C20="","",ROW()-8) | I20: =IF(OR(F20="",G20=""),"",ROUNDUP((G20-F20+1)/7,0)) | J20: =IF(C20="","",IF(AND(H20<>"",H20<=TODAY()),"라이브 Live",IF(F20="","미정 TBD",IF(TODAY()<F20,"예정 Planned",IF(AND(G20<>"",TODAY()>G20),"지연 Overdue","개발중 In Dev")))))
B21: =IF(C21="","",ROW()-8) | I21: =IF(OR(F21="",G21=""),"",ROUNDUP((G21-F21+1)/7,0)) | J21: =IF(C21="","",IF(AND(H21<>"",H21<=TODAY()),"라이브 Live",IF(F21="","미정 TBD",IF(TODAY()<F21,"예정 Planned",IF(AND(G21<>"",TODAY()>G21),"지연 Overdue","개발중 In Dev")))))
B22: =IF(C22="","",ROW()-8) | I22: =IF(OR(F22="",G22=""),"",ROUNDUP((G22-F22+1)/7,0)) | J22: =IF(C22="","",IF(AND(H22<>"",H22<=TODAY()),"라이브 Live",IF(F22="","미정 TBD",IF(TODAY()<F22,"예정 Planned",IF(AND(G22<>"",TODAY()>G22),"지연 Overdue","개발중 In Dev")))))
B23: =IF(C23="","",ROW()-8) | I23: =IF(OR(F23="",G23=""),"",ROUNDUP((G23-F23+1)/7,0)) | J23: =IF(C23="","",IF(AND(H23<>"",H23<=TODAY()),"라이브 Live",IF(F23="","미정 TBD",IF(TODAY()<F23,"예정 Planned",IF(AND(G23<>"",TODAY()>G23),"지연 Overdue","개발중 In Dev")))))
B24: =IF(C24="","",ROW()-8) | I24: =IF(OR(F24="",G24=""),"",ROUNDUP((G24-F24+1)/7,0)) | J24: =IF(C24="","",IF(AND(H24<>"",H24<=TODAY()),"라이브 Live",IF(F24="","미정 TBD",IF(TODAY()<F24,"예정 Planned",IF(AND(G24<>"",TODAY()>G24),"지연 Overdue","개발중 In Dev")))))
B25: =IF(C25="","",ROW()-8) | I25: =IF(OR(F25="",G25=""),"",ROUNDUP((G25-F25+1)/7,0)) | J25: =IF(C25="","",IF(AND(H25<>"",H25<=TODAY()),"라이브 Live",IF(F25="","미정 TBD",IF(TODAY()<F25,"예정 Planned",IF(AND(G25<>"",TODAY()>G25),"지연 Overdue","개발중 In Dev")))))
B26: =IF(C26="","",ROW()-8) | I26: =IF(OR(F26="",G26=""),"",ROUNDUP((G26-F26+1)/7,0)) | J26: =IF(C26="","",IF(AND(H26<>"",H26<=TODAY()),"라이브 Live",IF(F26="","미정 TBD",IF(TODAY()<F26,"예정 Planned",IF(AND(G26<>"",TODAY()>G26),"지연 Overdue","개발중 In Dev")))))
B27: =IF(C27="","",ROW()-8) | I27: =IF(OR(F27="",G27=""),"",ROUNDUP((G27-F27+1)/7,0)) | J27: =IF(C27="","",IF(AND(H27<>"",H27<=TODAY()),"라이브 Live",IF(F27="","미정 TBD",IF(TODAY()<F27,"예정 Planned",IF(AND(G27<>"",TODAY()>G27),"지연 Overdue","개발중 In Dev")))))
B28: =IF(C28="","",ROW()-8) | I28: =IF(OR(F28="",G28=""),"",ROUNDUP((G28-F28+1)/7,0)) | J28: =IF(C28="","",IF(AND(H28<>"",H28<=TODAY()),"라이브 Live",IF(F28="","미정 TBD",IF(TODAY()<F28,"예정 Planned",IF(AND(G28<>"",TODAY()>G28),"지연 Overdue","개발중 In Dev")))))
B29: =IF(C29="","",ROW()-8) | I29: =IF(OR(F29="",G29=""),"",ROUNDUP((G29-F29+1)/7,0)) | J29: =IF(C29="","",IF(AND(H29<>"",H29<=TODAY()),"라이브 Live",IF(F29="","미정 TBD",IF(TODAY()<F29,"예정 Planned",IF(AND(G29<>"",TODAY()>G29),"지연 Overdue","개발중 In Dev")))))
B30: =IF(C30="","",ROW()-8) | I30: =IF(OR(F30="",G30=""),"",ROUNDUP((G30-F30+1)/7,0)) | J30: =IF(C30="","",IF(AND(H30<>"",H30<=TODAY()),"라이브 Live",IF(F30="","미정 TBD",IF(TODAY()<F30,"예정 Planned",IF(AND(G30<>"",TODAY()>G30),"지연 Overdue","개발중 In Dev")))))
B31: =IF(C31="","",ROW()-8) | I31: =IF(OR(F31="",G31=""),"",ROUNDUP((G31-F31+1)/7,0)) | J31: =IF(C31="","",IF(AND(H31<>"",H31<=TODAY()),"라이브 Live",IF(F31="","미정 TBD",IF(TODAY()<F31,"예정 Planned",IF(AND(G31<>"",TODAY()>G31),"지연 Overdue","개발중 In Dev")))))
... B58: =IF(C58="","",ROW()-8) | I58: =IF(OR(F58="",G58=""),"",ROUNDUP((G58-F58+1)/7,0)) | J58: =IF(C58="","",IF(AND(H58<>"",H58<=TODAY()),"라이브 Live",IF(F58="","미정 TBD",IF(TODAY()<F58,"예정 Planned",IF(AND(G58<>"",TODAY()>G58),"지연 Overdue","개발중 In Dev")))))

Sheet 스위칭 업체 Switch vendors
A1: 스위칭 업체 Switch vendors | E1: 스위치 업체 자체와의 연동 (TGX·Shiji·Juniper·ZentrumHub 등) · 셀러(OMH 공급)·바이어(OMH 매입) 측 상태와 경유 파트너 수 · 오너 GSM (Aiden 인수 중, 12월~ Jane) Integration with the switch vendors themselves (TGX, Shiji, Juniper, ZentrumHub, etc.) · seller (OMH supply) and buyer (OMH sourcing) side status, partners routed via each switch · Owner: GSM (Aiden taking over, Jane lead from Dec)
A2: ="전체 Total "&COUNTA($G$5:$G$400)&" · 라이브 Live "&(COUNTIF($B$5:$B$400,"Live")+COUNTIF($B$5:$B$400,"Partially Live"))&" · 개발·테스트 Dev/Test "&(COUNTIF($B$5:$B$400,"In Development")+COUNTIF($B$5:$B$400,"Testing")+COUNTIF($B$5:$B$400,"Pending Live"))&" · 계약·NDA "&COUNTIF($B$5:$B$400,"NDA/Contract")&" · 파이프라인 Pipeline "&(COUNTIF($B$5:$B$400,"Pipeline")+COUNTIF($B$5:$B$400,"Contact"))&" · 60일+ 정체 Stalled 60d+ "&(COUNTIF($V$5:$V$400,"Stalled 60d+")+COUNTIF($V$5:$V$400,"Stalled 90d+")) -> 전체 Total 8 · 라이브 Live 0 · 개발·테스트 Dev/Test 2 · 계약·NDA 0 · 파이프라인 Pipeline 6 · 60일+ 정체 Stalled 60d+ 0 | AJ2: 단계 가중치 · Stage weight → | AK2: 0.05 | AL2: 0.1 | AM2: 0.15 | AN2: 0.2 | AO2: 0.3 | AP2: 0.4 | AQ2: 0.45 | AR2: 0.5 | AS2: 0.6 | AT2: 0.7 | AU2: 0.75 | AV2: 0.8 | AW2: 0.9 | AX2: 1
A3: 프로젝트 · 개발 정보 · Project / Dev Info | S3: 진행 · 체이스 현황 (자동 계산) · Progress & Chase Status (Auto-calculated) | AD3: 계획 · 이슈 (직접 입력) · Plan & Issues (manual entry) | AK3: 단계 이력 (실제 날짜) · Stage History (actual dates) — Pipeline → Contract → Dev → Customer Live
A4: No. | B4: 상태 Status | C4: 상태 수동 지정 Status override | D4: 보류/드롭 Hold/Drop | E4: 지역 Region | F4: 국가 Country | G4: 프로젝트 (업체) Project (Partner) | H4: 방향 Direction | I4: 셀러 측 (OMH 공급) Seller side (OMH supply) | J4: 바이어 측 (OMH 매입) Buyer side (OMH sourcing) | K4: 경유 파트너 수 Partners via this switch | L4: 연결 경로 Connection | M4: 원본 카테고리 Category (orig.) | N4: 비즈 임팩트 Biz Impact | O4: 영업 단계 (CRM) Sales stage (CRM) | P4: 담당 (현재) Owner (current) | Q4: 개발 주체 Dev Owner | R4: 처리 팀 Handling Team | S4: 진행률 Progress % | T4: 마지막 활동 Last Activity | U4: 단계 경과일 Days in Stage | V4: 지연 체크 Delay Check | W4: 현재 단계 Current Stage | X4: 파이프라인 기간 Pipeline Age | Y4: 체이스 # Chase # | Z4: 마지막 체이스 Last Chase | AA4: 체이스 후 경과일 Days Since Chase | AB4: 다음 체이스 Next Chase Due | AC4: 체이스 알림 Chase Alert | AD4: 목표 라이브 Target Go-Live | AE4: 대기 사유 Waiting On | AF4: 현황 · 다음 액션 (KR) Status · next action (KR) | AG4: 현황 · 다음 액션 (EN) Status · next action (EN) | AH4: 원본 Note (IT) Note (IT original) | AI4: 최종 연락 (CRM) Last contact (CRM) | AJ4: 출처 · 메모 Source · memo | AK4: ① 파이프라인 시작 Pipeline Start (5%) | AL4: ② 제안·소개 발송 Proposal / Intro Sent (10%) | AM4: ③ NDA 발송 NDA Sent (15%) | AN4: ④ NDA 체결 NDA Signed (20%) | AO4: ⑤ 계약 체결 Contract Signed (30%) | AP4: ⑥ SLA 확정 SLA Finalized (40%) | AQ4: ⑦ 개발 착수 예정 Dev Kickoff Planned (45%) | AR4: ⑧ 개발 착수 · SPEC/DEV 키 · 크리덴셜 Dev Kickoff / SPEC·DEV Key (50%) / Credential | AS4: ⑨ 인증 Certification (60%) | AT4: ⑩ 라이브 테스트 Live Test (70%) | AU4: ⑪ 개발 완료 예정 Dev Completion Planned (75%) | AV4: ⑫ 라이브 키 오픈 (OMH 측) Live Key Open – OMH side only (80%) | AW4: ⑬ 첫 예약 First Booking (90%) | AX4: ⑭ 고객 라이브 확정 (고객 통보) Customer Live Confirmed – client notified (100%)
A5: =IF($G5="","",ROW()-4) -> 1 | B5: =IF($G5="","",IF($C5<>"",$C5,IF($T5="","Contact",IF($S5>=1,"Live",IF($S5>=0.8,"Pending Live",IF($S5>=0.7,"Testing",IF($S5>=0.45,"In Development",IF($S5>=0.2,"NDA/Contract","Pipeline")))))))) -> Testing | E5: 중화권 · Greater China | F5: China | G5: Shiji | H5: 스위치 · Switch | I5: 진행 중 · In progress (셀러 인터페이스 10월 말~11월 초 · seller interface late Oct–early Nov, 첫 채널 Lion Travel · first channel Lion Travel) | J5: 테스트 완료 · Test done (인증 로그 전달만 남음 · only certification logs left) | K5: =COUNTIF('스위칭 연동 Switching'!$I$5:$I$400,"*Shiji*") -> 5 | L5: 스위치 자체 · Switch itself | M5: Switching System | N5: High | O5: API 연동 중 · Integrating | P5: GSM: Aiden → Jane (Dec~) | Q5: OHMY + Partner (50/50) | R5: SLA | S5: =IF($G5="","",IFERROR(LOOKUP(2,1/($AK5:$AX5<>""),$AK$2:$AX$2),0)) -> 0.7 | T5: =IF(COUNT($AK5:$AX5)=0,"",MAX($AK5:$AX5)) -> 46286 | U5: =IF($T5="","",TODAY()-$T5) -> 39 | V5: =IF($G5="","",IF($T5="","No Record",IF(OR($S5>=1,$C5="Live"),"Live",IF($U5>=90,"Stalled 90d+",IF($U5>=60,"Stalled 60d+",IF($U5>=30,"Stalled 30d+","In Progress")))))) -> Stalled 30d+ | W5: =IF(COUNT($AK5:$AX5)=0,"",LOOKUP(2,1/($AK5:$AX5<>""),{"① 파이프라인 시작 · Pipeline Start","② 제안·소개 발송 · Proposal Sent","③ NDA 발송 · NDA Sent","④ NDA 체결 · NDA Signed","⑤ 계약 체결 · Contract Signed","⑥ SLA 확정 · SLA Finalized","⑦ 개발 착수 예정 · Kickoff Planned","⑧ 개발 착수 · SPEC/DEV 키 · 크리덴셜 · Kickoff / Credential","⑨ 인증 · Certification","⑩ 라이브 테스트 · Live Test","⑪ 개발 완료 예정 · Dev Complete Planned","⑫ 라이브 키 오픈 (OMH 측) · Live Key Open","⑬ 첫 예약 · First Booking","⑭ 고객 라이브 확정 (고객 통보) · Customer Live"})) -> ⑩ 라이브 테스트 · Live Test | X5: =IF(COUNT($AK5:$AX5)=0,"",IF(N($S5)>=1,MAX($AK5:$AX5),TODAY())-MIN($AK5:$AX5)) -> 821 | Y5: =IF($G5="","",COUNTIF('Chase Log'!$B$4:$B$2000,$G5)) -> 2 | Z5: =IF(N($Y5)=0,"",_xlfn.MAXIFS('Chase Log'!$E$4:$E$2000,'Chase Log'!$B$4:$B$2000,$G5)) -> 46303 | AA5: =IF($Z5="","",TODAY()-$Z5) -> 22 | AB5: =IF($Z5="","",IF(OR(AND($T5<>"",N($T5)>N($Z5)),COUNTIFS('Chase Log'!$B$4:$B$2000,$G5,'Chase Log'!$E$4:$E$2000,$Z5,'Chase Log'!$I$4:$I$2000,"Y")>0),"",IF(_xlfn.MAXIFS('Chase Log'!$J$4:$J$2000,'Chase Log'!$B$4:$B$2000,$G5,'Chase Log'!$E$4:$E$2000,$Z5)=0,"",_xlfn.MAXIFS('Chase Log'!$J$4:$J$2000,'Chase Log'!$B$4:$B$2000,$G5,'Chase Log'!$E$4:$E$2000,$Z5)))) -> 46310 | AC5: =IF(OR($G5="",N($S5)>=1,$C5="Live",$D5<>""),"",IF(AND($AB5<>"",N($AB5)>0),IF($AB5<TODAY(),"Chase Overdue","Scheduled"),IF(AND($T5<>"",N($U5)>='안내 Guide'!$D$4,OR($AA5="",N($AA5)>='안내 Guide'!$D$4)),"Chase Needed",""))) -> Chase Overdue | AD5: 46302 | AF5: Ace Zhou 리캡 회신 — 마켓플레이스(셀러 2%) 진행 여부 결정 + 바이어 인증용 실행 로그 전달 | AG5: Reply to Ace Zhou's recap — decide whether to proceed with the marketplace (seller 2%) + send execution logs for buyer certification | AH5: Btw, regarding Shiji, current status is separate : Shiji (OMH are supply) : Shiji is doing it Shiji (OMH are demand - 3rd party integration) : Finish implementation, we're testing with them. | AI5: 2026-10-16 | AJ5: Tracker | AN5: 45504 | AO5: 46199 | AQ5: 46237 | AR5: 46267 | AS5: 46281 | AT5: 46286
A6: =IF($G6="","",ROW()-4) -> 2 | B6: =IF($G6="","",IF($C6<>"",$C6,IF($T6="","Contact",IF($S6>=1,"Live",IF($S6>=0.8,"Pending Live",IF($S6>=0.7,"Testing",IF($S6>=0.45,"In Development",IF($S6>=0.2,"NDA/Contract","Pipeline")))))))) -> In Development | E6: 유럽·미주 · Europe & Americas | F6: Spain | G6: TGX | H6: 스위치 · Switch | I6: 개발 중 · In development (인증 60% · certification 60%, Buyer 계약 1건 필요 · needs 1 buyer contract) | J6: 미확인 · Unconfirmed | K6: =COUNTIF('스위칭 연동 Switching'!$I$5:$I$400,"*TGX*") -> 13 | L6: 스위치 자체 · Switch itself | M6: Switching System | N6: High | O6: API 연동 중 · Integrating | P6: GSM: Aiden → Jane (Dec~) | Q6: OHMY + Partner (50/50) | R6: SLA | S6: =IF($G6="","",IFERROR(LOOKUP(2,1/($AK6:$AX6<>""),$AK$2:$AX$2),0)) -> 0.6 | T6: =IF(COUNT($AK6:$AX6)=0,"",MAX($AK6:$AX6)) -> 46287 | U6: =IF($T6="","",TODAY()-$T6) -> 38 | V6: =IF($G6="","",IF($T6="","No Record",IF(OR($S6>=1,$C6="Live"),"Live",IF($U6>=90,"Stalled 90d+",IF($U6>=60,"Stalled 60d+",IF($U6>=30,"Stalled 30d+","In Progress")))))) -> Stalled 30d+ | W6: =IF(COUNT($AK6:$AX6)=0,"",LOOKUP(2,1/($AK6:$AX6<>""),{"① 파이프라인 시작 · Pipeline Start","② 제안·소개 발송 · Proposal Sent","③ NDA 발송 · NDA Sent","④ NDA 체결 · NDA Signed","⑤ 계약 체결 · Contract Signed","⑥ SLA 확정 · SLA Finalized","⑦ 개발 착수 예정 · Kickoff Planned","⑧ 개발 착수 · SPEC/DEV 키 · 크리덴셜 · Kickoff / Credential","⑨ 인증 · Certification","⑩ 라이브 테스트 · Live Test","⑪ 개발 완료 예정 · Dev Complete Planned","⑫ 라이브 키 오픈 (OMH 측) · Live Key Open","⑬ 첫 예약 · First Booking","⑭ 고객 라이브 확정 (고객 통보) · Customer Live"})) -> ⑨ 인증 · Certification | X6: =IF(COUNT($AK6:$AX6)=0,"",IF(N($S6)>=1,MAX($AK6:$AX6),TODAY())-MIN($AK6:$AX6)) -> 38 | Y6: =IF($G6="","",COUNTIF('Chase Log'!$B$4:$B$2000,$G6)) -> 1 | Z6: =IF(N($Y6)=0,"",_xlfn.MAXIFS('Chase Log'!$E$4:$E$2000,'Chase Log'!$B$4:$B$2000,$G6)) -> 46300 | AA6: =IF($Z6="","",TODAY()-$Z6) -> 25 | AB6: =IF($Z6="","",IF(OR(AND($T6<>"",N($T6)>N($Z6)),COUNTIFS('Chase Log'!$B$4:$B$2000,$G6,'Chase Log'!$E$4:$E$2000,$Z6,'Chase Log'!$I$4:$I$2000,"Y")>0),"",IF(_xlfn.MAXIFS('Chase Log'!$J$4:$J$2000,'Chase Log'!$B$4:$B$2000,$G6,'Chase Log'!$E$4:$E$2000,$Z6)=0,"",_xlfn.MAXIFS('Chase Log'!$J$4:$J$2000,'Chase Log'!$B$4:$B$2000,$G6,'Chase Log'!$E$4:$E$2000,$Z6)))) | AC6: =IF(OR($G6="",N($S6)>=1,$C6="Live",$D6<>""),"",IF(AND($AB6<>"",N($AB6)>0),IF($AB6<TODAY(),"Chase Overdue","Scheduled"),IF(AND($T6<>"",N($U6)>='안내 Guide'!$D$4,OR($AA6="",N($AA6)>='안내 Guide'!$D$4)),"Chase Needed",""))) -> Chase Needed | AF6: OMH TGX 개발 완료 일정 확보 + Buyer 계약 1건(VOLT 또는 Welcomebeds) 확정 | AG6: Secure OMH TGX development completion date + confirm one Buyer contract (VOLT or Welcomebeds) | AI6: 2026-09-15 | AJ6: Tracker | AS6: 46287
A7: =IF($G7="","",ROW()-4) -> 3 | B7: =IF($G7="","",IF($C7<>"",$C7,IF($T7="","Contact",IF($S7>=1,"Live",IF($S7>=0.8,"Pending Live",IF($S7>=0.7,"Testing",IF($S7>=0.45,"In Development",IF($S7>=0.2,"NDA/Contract","Pipeline")))))))) -> Contact | E7: 인도 · India | F7: India | G7: Zentrumhub | H7: 스위치 · Switch | I7: 미확인 · Unconfirmed | J7: 미확인 · Unconfirmed | K7: =COUNTIF('스위칭 연동 Switching'!$I$5:$I$400,"*ZentrumHub*") -> 1 | L7: 스위치 자체 · Switch itself | O7: 신규 개발 · New lead | P7: GSM: Aiden → Jane (Dec~) | S7: =IF($G7="","",IFERROR(LOOKUP(2,1/($AK7:$AX7<>""),$AK$2:$AX$2),0)) -> 0 | T7: =IF(COUNT($AK7:$AX7)=0,"",MAX($AK7:$AX7)) | U7: =IF($T7="","",TODAY()-$T7) | V7: =IF($G7="","",IF($T7="","No Record",IF(OR($S7>=1,$C7="Live"),"Live",IF($U7>=90,"Stalled 90d+",IF($U7>=60,"Stalled 60d+",IF($U7>=30,"Stalled 30d+","In Progress")))))) -> No Record | W7: =IF(COUNT($AK7:$AX7)=0,"",LOOKUP(2,1/($AK7:$AX7<>""),{"① 파이프라인 시작 · Pipeline Start","② 제안·소개 발송 · Proposal Sent","③ NDA 발송 · NDA Sent","④ NDA 체결 · NDA Signed","⑤ 계약 체결 · Contract Signed","⑥ SLA 확정 · SLA Finalized","⑦ 개발 착수 예정 · Kickoff Planned","⑧ 개발 착수 · SPEC/DEV 키 · 크리덴셜 · Kickoff / Credential","⑨ 인증 · Certification","⑩ 라이브 테스트 · Live Test","⑪ 개발 완료 예정 · Dev Complete Planned","⑫ 라이브 키 오픈 (OMH 측) · Live Key Open","⑬ 첫 예약 · First Booking","⑭ 고객 라이브 확정 (고객 통보) · Customer Live"})) | X7: =IF(COUNT($AK7:$AX7)=0,"",IF(N($S7)>=1,MAX($AK7:$AX7),TODAY())-MIN($AK7:$AX7)) | Y7: =IF($G7="","",COUNTIF('Chase Log'!$B$4:$B$2000,$G7)) -> 3 | Z7: =IF(N($Y7)=0,"",_xlfn.MAXIFS('Chase Log'!$E$4:$E$2000,'Chase Log'!$B$4:$B$2000,$G7)) -> 46322 | AA7: =IF($Z7="","",TODAY()-$Z7) -> 3 | AB7: =IF($Z7="","",IF(OR(AND($T7<>"",N($T7)>N($Z7)),COUNTIFS('Chase Log'!$B$4:$B$2000,$G7,'Chase Log'!$E$4:$E$2000,$Z7,'Chase Log'!$I$4:$I$2000,"Y")>0),"",IF(_xlfn.MAXIFS('Chase Log'!$J$4:$J$2000,'Chase Log'!$B$4:$B$2000,$G7,'Chase Log'!$E$4:$E$2000,$Z7)=0,"",_xlfn.MAXIFS('Chase Log'!$J$4:$J$2000,'Chase Log'!$B$4:$B$2000,$G7,'Chase Log'!$E$4:$E$2000,$Z7)))) -> 46329 | AC7: =IF(OR($G7="",N($S7)>=1,$C7="Live",$D7<>""),"",IF(AND($AB7<>"",N($AB7)>0),IF($AB7<TODAY(),"Chase Overdue","Scheduled"),IF(AND($T7<>"",N($U7)>='안내 Guide'!$D$4,OR($AA7="",N($AA7)>='안내 Guide'!$D$4)),"Chase Needed",""))) -> Scheduled | AF7: GSM 인수 후 진행 상태 확인, 추가 스위치 여부는 Shiji·TGX 완료 후 판단 | AG7: Check progress after GSM takeover; decide on additional switches after Shiji and TGX are complete | AI7: 2026-10-05 | AJ7: CRM 추가 · Added from CRM (Tracker 미등록 · not in Tracker; 단계 날짜는 확인되는 대로 입력 · add stage dates when confirmed)
A8: =IF($G8="","",ROW()-4) -> 4 | B8: =IF($G8="","",IF($C8<>"",$C8,IF($T8="","Contact",IF($S8>=1,"Live",IF($S8>=0.8,"Pending Live",IF($S8>=0.7,"Testing",IF($S8>=0.45,"In Development",IF($S8>=0.2,"NDA/Contract","Pipeline")))))))) -> Contact | D8: Dropped | E8: 한국 · Korea | F8: Korea | G8: 11infortec | H8: 스위치 · Switch | I8: 미확인 · Unconfirmed | J8: 미확인 · Unconfirmed | K8: =COUNTIF('스위칭 연동 Switching'!$I$5:$I$400,"*11infortec*") -> 0 | L8: 스위치 자체 · Switch itself | M8: Switching System | N8: Low | O8: — | P8: GSM: Aiden → Jane (Dec~) | Q8: OHMY | R8: SLA | S8: =IF($G8="","",IFERROR(LOOKUP(2,1/($AK8:$AX8<>""),$AK$2:$AX$2),0)) -> 0 | T8: =IF(COUNT($AK8:$AX8)=0,"",MAX($AK8:$AX8)) | U8: =IF($T8="","",TODAY()-$T8) | V8: =IF($G8="","",IF($T8="","No Record",IF(OR($S8>=1,$C8="Live"),"Live",IF($U8>=90,"Stalled 90d+",IF($U8>=60,"Stalled 60d+",IF($U8>=30,"Stalled 30d+","In Progress")))))) -> No Record | W8: =IF(COUNT($AK8:$AX8)=0,"",LOOKUP(2,1/($AK8:$AX8<>""),{"① 파이프라인 시작 · Pipeline Start","② 제안·소개 발송 · Proposal Sent","③ NDA 발송 · NDA Sent","④ NDA 체결 · NDA Signed","⑤ 계약 체결 · Contract Signed","⑥ SLA 확정 · SLA Finalized","⑦ 개발 착수 예정 · Kickoff Planned","⑧ 개발 착수 · SPEC/DEV 키 · 크리덴셜 · Kickoff / Credential","⑨ 인증 · Certification","⑩ 라이브 테스트 · Live Test","⑪ 개발 완료 예정 · Dev Complete Planned","⑫ 라이브 키 오픈 (OMH 측) · Live Key Open","⑬ 첫 예약 · First Booking","⑭ 고객 라이브 확정 (고객 통보) · Customer Live"})) | X8: =IF(COUNT($AK8:$AX8)=0,"",IF(N($S8)>=1,MAX($AK8:$AX8),TODAY())-MIN($AK8:$AX8)) | Y8: =IF($G8="","",COUNTIF('Chase Log'!$B$4:$B$2000,$G8)) -> 0 | Z8: =IF(N($Y8)=0,"",_xlfn.MAXIFS('Chase Log'!$E$4:$E$2000,'Chase Log'!$B$4:$B$2000,$G8)) | AA8: =IF($Z8="","",TODAY()-$Z8) | AB8: =IF($Z8="","",IF(OR(AND($T8<>"",N($T8)>N($Z8)),COUNTIFS('Chase Log'!$B$4:$B$2000,$G8,'Chase Log'!$E$4:$E$2000,$Z8,'Chase Log'!$I$4:$I$2000,"Y")>0),"",IF(_xlfn.MAXIFS('Chase Log'!$J$4:$J$2000,'Chase Log'!$B$4:$B$2000,$G8,'Chase Log'!$E$4:$E$2000,$Z8)=0,"",_xlfn.MAXIFS('Chase Log'!$J$4:$J$2000,'Chase Log'!$B$4:$B$2000,$G8,'Chase Log'!$E$4:$E$2000,$Z8)))) | AC8: =IF(OR($G8="",N($S8)>=1,$C8="Live",$D8<>""),"",IF(AND($AB8<>"",N($AB8)>0),IF($AB8<TODAY(),"Chase Overdue","Scheduled"),IF(AND($T8<>"",N($U8)>='안내 Guide'!$D$4,OR($AA8="",N($AA8)>='안내 Guide'!$D$4)),"Chase Needed",""))) | AJ8: Tracker
A9: =IF($G9="","",ROW()-4) -> 5 | B9: =IF($G9="","",IF($C9<>"",$C9,IF($T9="","Contact",IF($S9>=1,"Live",IF($S9>=0.8,"Pending Live",IF($S9>=0.7,"Testing",IF($S9>=0.45,"In Development",IF($S9>=0.2,"NDA/Contract","Pipeline")))))))) -> Contact | D9: On Hold | E9: 중화권 · Greater China | F9: China | G9: Derbysoft | H9: 스위치 · Switch | I9: 미확인 · Unconfirmed | J9: 미확인 · Unconfirmed | K9: =COUNTIF('스위칭 연동 Switching'!$I$5:$I$400,"*Derbysoft*") -> 0 | L9: 스위치 자체 · Switch itself | M9: Switching System | N9: Low | O9: — | P9: GSM: Aiden → Jane (Dec~) | Q9: OHMY | R9: SLA | S9: =IF($G9="","",IFERROR(LOOKUP(2,1/($AK9:$AX9<>""),$AK$2:$AX$2),0)) -> 0 | T9: =IF(COUNT($AK9:$AX9)=0,"",MAX($AK9:$AX9)) | U9: =IF($T9="","",TODAY()-$T9) | V9: =IF($G9="","",IF($T9="","No Record",IF(OR($S9>=1,$C9="Live"),"Live",IF($U9>=90,"Stalled 90d+",IF($U9>=60,"Stalled 60d+",IF($U9>=30,"Stalled 30d+","In Progress")))))) -> No Record | W9: =IF(COUNT($AK9:$AX9)=0,"",LOOKUP(2,1/($AK9:$AX9<>""),{"① 파이프라인 시작 · Pipeline Start","② 제안·소개 발송 · Proposal Sent","③ NDA 발송 · NDA Sent","④ NDA 체결 · NDA Signed","⑤ 계약 체결 · Contract Signed","⑥ SLA 확정 · SLA Finalized","⑦ 개발 착수 예정 · Kickoff Planned","⑧ 개발 착수 · SPEC/DEV 키 · 크리덴셜 · Kickoff / Credential","⑨ 인증 · Certification","⑩ 라이브 테스트 · Live Test","⑪ 개발 완료 예정 · Dev Complete Planned","⑫ 라이브 키 오픈 (OMH 측) · Live Key Open","⑬ 첫 예약 · First Booking","⑭ 고객 라이브 확정 (고객 통보) · Customer Live"})) | X9: =IF(COUNT($AK9:$AX9)=0,"",IF(N($S9)>=1,MAX($AK9:$AX9),TODAY())-MIN($AK9:$AX9)) | Y9: =IF($G9="","",COUNTIF('Chase Log'!$B$4:$B$2000,$G9)) -> 0 | Z9: =IF(N($Y9)=0,"",_xlfn.MAXIFS('Chase Log'!$E$4:$E$2000,'Chase Log'!$B$4:$B$2000,$G9)) | AA9: =IF($Z9="","",TODAY()-$Z9) | AB9: =IF($Z9="","",IF(OR(AND($T9<>"",N($T9)>N($Z9)),COUNTIFS('Chase Log'!$B$4:$B$2000,$G9,'Chase Log'!$E$4:$E$2000,$Z9,'Chase Log'!$I$4:$I$2000,"Y")>0),"",IF(_xlfn.MAXIFS('Chase Log'!$J$4:$J$2000,'Chase Log'!$B$4:$B$2000,$G9,'Chase Log'!$E$4:$E$2000,$Z9)=0,"",_xlfn.MAXIFS('Chase Log'!$J$4:$J$2000,'Chase Log'!$B$4:$B$2000,$G9,'Chase Log'!$E$4:$E$2000,$Z9)))) | AC9: =IF(OR($G9="",N($S9)>=1,$C9="Live",$D9<>""),"",IF(AND($AB9<>"",N($AB9)>0),IF($AB9<TODAY(),"Chase Overdue","Scheduled"),IF(AND($T9<>"",N($U9)>='안내 Guide'!$D$4,OR($AA9="",N($AA9)>='안내 Guide'!$D$4)),"Chase Needed",""))) | AJ9: Tracker
